Workbook

Sheet სახელმძღვანელო
B2: 1) გახსენით "პარამეტრების" ფურცელი და მოირგეთ კატეგორიები თქვენს საჭიროებებზე. შეგიძლიათ წაშალოთ ის, რაც არ გჭირდებათ და დაამატოთ ყველაფერი, რაც აკლია.
B33: 2) მიმდინარე თვის ფურცელზე ორჯერ დააწკაპუნეთ უჯრედზე F5 (ზედა მარცხნივ) და შეიყვანეთ თქვენი საწყისი თანხა.
B41: 3) შეიყვანეთ მხოლოდ თქვენი დაგეგმილი ხარჯები, შემოსავალი და ვალები, რომელთა გადახდასაც აპირებთ. თქვენ არ გჭირდებათ ფაქტობრივი თანხების შევსება! ისინი ავტომატურად გაიყვანება შემდეგი ნაბიჯიდან. კატეგორიები გამოყვანილია" პარამეტრების " ფურცლიდან.
B57: 4) ჩაწერეთ თქვენი რეალური შემოსავალი და ხარჯები ყოველდღიურად!
B71: 5) იხილეთ "მაგალითი" ფურცელი ნიმუში, თუ როგორია შევსებული ფურცელი.
B74: მზადაა! ახლა თქვენ გაქვთ ტრეკერის საკუთარი ასლი. გამოიყენეთ ტრეკერი ყოველდღე და უყურეთ, თუ როგორ იწვევს მცირე ნაბიჯები დიდ შედეგებს! თუ თქვენ გაქვთ რაიმე შეკითხვები, მოგვწერეთ.

Sheet პარამეტრები
B2: პარამეტრები
B7: შემოსავალი | E7: ხარჯები | G7: ვალი
B8: ხელფასი | E8: ქირა | G8: სესხები
B9: ბონუსი | E9: მობილური ტელეფონი | G9: ვალები
B10: ფრილანსერობა | E10: ინტერნეტი | G10: საკრედიტო ბარათები
B11: ბიზნესი | E11: დაზღვევა | G11: იპოთეკა
B12: ინვესტიციები და დეპოზიტები | E12: საწევრო | G12: ვალდებულებები
B13: სხვა შემოსავალი | E13: კომუნალური
B14: შემოსავალი ოჯახიდან | E14: ოჯახი
B15: შემოსავალი მესამე პირიდან | E15: შინაური ცხოველები
B16: ვალის დაბრუნება | E16: პირადი
B17: ნივთის გაყიდვა | E17: თავის მოვლა
B18: სტიპენდია / გრანტი | E18: ქველმოქმედება
B19: დივიდენდები | E19: ტრანსპორტი
E20: ტაქსი
E21: საჭმელი
E22: კაფეები და რესტორნები
E23: მანქანა
E24: საწვავი
E25: მოგზაურობა
E26: წამლები
E27: გართობა
E28: სასმელი
E29: სიგარეტი
E30: შოპინგი
E31: ტანსაცმელი
... E33: სპორტი

Sheet მაგალითი
AQ1: расходы | AR1: ='პარამეტრები'!E8 -> ქირა | AV1: ='პარამეტრები'!B8 -> ხელფასი | AW1: доходы | BA1: Сводка
AR2: ='პარამეტრები'!E9 -> მობილური ტელეფონი | AV2: ='პარამეტრები'!B9 -> ბონუსი | BA2: Наименование | BF2: Plan | BI2: Actual
C3: ნოემბერი | I3: შემოსავალი | N3: ხარჯი | S3: ბალანსი | X3: მთლიანი ბალანსი | AC3: ვალი | AF3: ტენდენციები | AR3: ='პარამეტრები'!E10 -> ინტერნეტი | AV3: ='პარამეტრები'!B10 -> ფრილანსერობა | BA3: Income | BF3: =S40 -> 7000 | BI3: =SUM(AB44:AD143) -> 7100
I4: გეგმა | K4: რეალობა | N4: გეგმა | P4: რეალობა | S4: გეგმა | U4: რეალობა | X4: გეგმა | Z4: რეალობა | AC4: =BF7 -> 100 | AF4: გეგმა | AH4: რეალობა | AR4: ='პარამეტრები'!E11 -> დაზღვევა | AV4: ='პარამეტრები'!B11 -> ბიზნესი | BA4: Expenses | BF4: =G40+SUM(AE28:AG39) -> 4610 | BI4: =SUM(J44:L143) -> 3098
C5: საწყისი თანხა | F5: 8000 | I5: =BF3 -> 7000 | K5: =BI3 -> 7100 | N5: =BF4 -> 4610 | P5: =BI4 -> 3098 | S5: =BF5 -> 2790 | U5: =BI5 -> 4002 | X5: =BF6 -> 10790 | Z5: =BI6 -> 12002 | AF5: 0 | AH5: 0 | AR5: ='პარამეტრები'!E12 -> საწევრო | AV5: ='პარამეტრები'!B12 -> ინვესტიციები და დეპოზიტები | BA5: Остаток | BF5: =S40-G40-AE40 -> 2790 | BI5: =SUM(AB44:AD143)-SUM(J44:L143) -> 4002
AR6: ='პარამეტრები'!E13 -> კომუნალური | AV6: ='პარამეტრები'!B13 -> სხვა შემოსავალი | BA6: Общий остаток | BF6: =F5+BF5 -> 10790 | BI6: =F5+BI5 -> 12002
AR7: ='პარამეტრები'!E14 -> ოჯახი | AV7: ='პარამეტრები'!B14 -> შემოსავალი ოჯახიდან | BA7: Долги | BF7: =AE40 -> 100
B8: ხარჯები კატეგორიის მიხედვით | N8: გეგმა / რეალობა | Z8: შემოსავალი კატეგორიის მიხედვით | AR8: ='პარამეტრები'!E15 -> შინაური ცხოველები | AV8: ='პარამეტრები'!B15 -> შემოსავალი მესამე პირიდან | BA8: Тренд расходов | BF8: 0
AR9: ='პარამეტრები'!E16 -> პირადი | AV9: ='პარამეტრები'!B16 -> ვალის დაბრუნება | BA9: Тренд доходов | BF9: 0
AR10: ='პარამეტრები'!E17 -> თავის მოვლა | AV10: ='პარამეტრები'!B17 -> ნივთის გაყიდვა
AR11: ='პარამეტრები'!E18 -> ქველმოქმედება | AV11: ='პარამეტრები'!B18 -> სტიპენდია / გრანტი
AR12: ='პარამეტრები'!E19 -> ტრანსპორტი | AV12: ='პარამეტრები'!B19 -> დივიდენდები
AR13: ='პარამეტრები'!E20 -> ტაქსი | AV13: ='პარამეტრები'!B20
AR14: ='პარამეტრები'!E21 -> საჭმელი | AV14: ='პარამეტრები'!B21
AR15: ='პარამეტრები'!E22 -> კაფეები და რესტორნები | AV15: ='პარამეტრები'!B22
AR16: ='პარამეტრები'!E23 -> მანქანა | AV16: ='პარამეტრები'!B23
AR17: ='პარამეტრები'!E24 -> საწვავი | AV17: ='პარამეტრები'!B24
AR18: ='პარამეტრები'!E25 -> მოგზაურობა | AV18: ='პარამეტრები'!B25
AR19: ='პარამეტრები'!E26 -> წამლები | AV19: ='პარამეტრები'!B26
AR20: ='პარამეტრები'!E27 -> გართობა | AV20: ='პარამეტრები'!B27
AR21: ='პარამეტრები'!E28 -> სასმელი | AV21: ='პარამეტრები'!B28
... AR25: ='პარამეტრები'!E32 -> განათლება | AV25: ='პარამეტრები'!B32
B26: დაგეგმილი ხარჯები | N26: დაგეგმილი შემოსავალი | Z26: ვალი | AR26: ='პარამეტრები'!E33 -> სპორტი | AV26: ='პარამეტრები'!B33
B27: წყარო | G27: გეგმა | J27: რეალობა | N27: წყარო | S27: გეგმა | V27: რეალობა | Z27: წყარო | AE27: ვალი | AH27: რეალობა | AR27: ='პარამეტრები'!E34 | AV27: ='პარამეტრები'!B34
B28: ქირა | G28: 3000 | J28: =SUMIF($E$44:$I$143,B28,$J$44:$L$143) -> 2000 | N28: ხელფასი | S28: 5000 | V28: =SUMIF($W$44:$AA$143,N28,$AB$44:$AD$143) -> 5000 | Z28: ვალები | AE28: 500 | AH28: =SUMIF($E$44:$I$143,Z28,$J$44:$L$143) -> 400 | AR28: ='პარამეტრები'!E35 | AV28: ='პარამეტრები'!B35
B29: მობილური ტელეფონი | G29: 30 | J29: =SUMIF($E$44:$I$143,B29,$J$44:$L$143) -> 30 | N29: ბიზნესი | S29: 2000 | V29: =SUMIF($W$44:$AA$143,N29,$AB$44:$AD$143) -> 2100 | AH29: =SUMIF($E$44:$I$143,Z29,$J$44:$L$143) -> 0 | AR29: ='პარამეტრები'!E36 | AV29: ='პარამეტრები'!B36
B30: ინტერნეტი | G30: 30 | J30: =SUMIF($E$44:$I$143,B30,$J$44:$L$143) -> 30 | V30: =SUMIF($W$44:$AA$143,N30,$AB$44:$AD$143) -> 0 | AH30: =SUMIF($E$44:$I$143,Z30,$J$44:$L$143) -> 0 | AR30: ='პარამეტრები'!E37 | AV30: ='პარამეტრები'!B37 | AZ30: ='Настройка'!B32 -> #REF!
B31: საწევრო | G31: 50 | J31: =SUMIF($E$44:$I$143,B31,$J$44:$L$143) -> 8 | V31: =SUMIF($W$44:$AA$143,N31,$AB$44:$AD$143) -> 0 | AH31: =SUMIF($E$44:$I$143,Z31,$J$44:$L$143) -> 0 | AR31: ='პარამეტრები'!E38 | AV31: ='პარამეტრები'!B38 | AZ31: ='Настройка'!B33 -> #REF!
B32: საჭმელი | G32: 1000 | J32: =SUMIF($E$44:$I$143,B32,$J$44:$L$143) -> 500 | V32: =SUMIF($W$44:$AA$143,N32,$AB$44:$AD$143) -> 0 | AH32: =SUMIF($E$44:$I$143,Z32,$J$44:$L$143) -> 0 | AR32: ='პარამეტრები'!E39 | AV32: ='პარამეტრები'!B39 | AZ32: ='Настройка'!B34 -> #REF!
J33: =SUMIF($E$44:$I$143,B33,$J$44:$L$143) -> 0 | V33: =SUMIF($W$44:$AA$143,N33,$AB$44:$AD$143) -> 0 | AH33: =SUMIF($E$44:$I$143,Z33,$J$44:$L$143) -> 0 | AR33: ='პარამეტრები'!E40 | AV33: ='პარამეტრები'!B40 | AZ33: ='Настройка'!B35 -> #REF!
J34: =SUMIF($E$44:$I$143,B34,$J$44:$L$143) -> 0 | V34: =SUMIF($W$44:$AA$143,N34,$AB$44:$AD$143) -> 0 | AH34: =SUMIF($E$44:$I$143,Z34,$J$44:$L$143) -> 0 | AR34: ='პარამეტრები'!E41 | AV34: ='პარამეტრები'!B41 | AZ34: ='Настройка'!B36 -> #REF!
J35: =SUMIF($E$44:$I$143,B35,$J$44:$L$143) -> 0 | V35: =SUMIF($W$44:$AA$143,N35,$AB$44:$AD$143) -> 0 | AH35: =SUMIF($E$44:$I$143,Z35,$J$44:$L$143) -> 0 | AQ35: Долги | AR35: ='პარამეტრები'!G8 -> სესხები | AV35: ='პარამეტრები'!B42 | AZ35: ='Настройка'!B37 -> #REF!
J36: =SUMIF($E$44:$I$143,B36,$J$44:$L$143) -> 0 | V36: =SUMIF($W$44:$AA$143,N36,$AB$44:$AD$143) -> 0 | AH36: =SUMIF($E$44:$I$143,Z36,$J$44:$L$143) -> 0 | AR36: ='პარამეტრები'!G9 -> ვალები | AV36: ='პარამეტრები'!B43
J37: =SUMIF($E$44:$I$143,B37,$J$44:$L$143) -> 0 | V37: =SUMIF($W$44:$AA$143,N37,$AB$44:$AD$143) -> 0 | AH37: =SUMIF($E$44:$I$143,Z37,$J$44:$L$143) -> 0 | AR37: ='პარამეტრები'!G10 -> საკრედიტო ბარათები | AV37: ='პარამეტრები'!B44
J38: =SUMIF($E$44:$I$143,B38,$J$44:$L$143) -> 0 | V38: =SUMIF($W$44:$AA$143,N38,$AB$44:$AD$143) -> 0 | AH38: =SUMIF($E$44:$I$143,Z38,$J$44:$L$143) -> 0 | AR38: ='პარამეტრები'!G11 -> იპოთეკა | AV38: ='პარამეტრები'!B45
J39: =SUMIF($E$44:$I$143,B39,$J$44:$L$143) -> 0 | V39: =SUMIF($W$44:$AA$143,N39,$AB$44:$AD$143) -> 0 | AH39: =SUMIF($E$44:$I$143,Z39,$J$44:$L$143) -> 0 | AR39: ='პარამეტრები'!G12 -> ვალდებულებები | AV39: ='პარამეტრები'!B46
B40: სულ | G40: =SUM(G28:I39) -> 4110 | J40: =SUM(J28:L39) -> 2568 | N40: სულ | S40: =SUM(S28:U39) -> 7000 | V40: =SUM(V28:X39) -> 7100 | Z40: სულ | AE40: =SUM(AE28:AG39)-AH40 -> 100 | AH40: =SUM(AH28:AJ39) -> 400 | AR40: ='პარამეტრები'!G13 | AV40: ='პარამეტრები'!B47
AR41: ='პარამეტრები'!G14
B42: ყოველდღიური ხარჯები | T42: ყოველდღიური შემოსავალი | AR42: ='პარამეტრები'!G15
B43: თარიღი | E43: კატეგორია | J43: თანხა | M43: კომენტარი | T43: თარიღი | W43: კატეგორია | AB43: თანხა | AE43: კომენტარი | AR43: ='პარამეტრები'!G16
...

Sheet მთავარი
AQ1: расходы | AR1: ='Настройка'!E8 -> #REF! | AV1: ='Настройка'!B8 -> #REF! | AW1: доходы | BA1: Сводка
AR2: ='Настройка'!E9 -> #REF! | AV2: ='Настройка'!B9 -> #REF! | BA2: Наименование | BF2: План | BI2: Факт | BM2: Траты | BO2: Доходы
B3: წლიური რეზიუმე | N3: შემოსავალი | S3: ხარჯი | X3: ბალანსი | AR3: ='Настройка'!E10 -> #REF! | AV3: ='Настройка'!B10 -> #REF! | BA3: Доходы | BF3: =S40 | BI3: =SUM(AB44:AD143) -> 0 | BM3: ='Настройка'!E8 -> #REF! | BN3: =SUMIF('Ноя'!$E$44:$I$143,BM3,'Ноя'!$J$44:$L$143)+SUMIF('Дек'!$E$44:$I$143,BM3,'Дек'!$J$44:$L$143)+SUMIF('Янв'!$E$44:$I$143,BM3,'Янв'!$J$44:$L$143)+SUMIF('Фев'!$E$44:$I$143,BM3,'Фев'!$J$44:$L$143)+SUMIF('Мар'!$E$44:$I$143,BM3,'Мар'!$J$44:$L$143)+SUMIF('Апр'!$E$44:$I$143,BM3,'Апр'!$J$44:$L$143)+SUMIF('Май'!$E$44:$I$143,BM3,'Май'!$J$44:$L$143)+SUMIF('Июн'!$E$44:$I$143,BM3,'Июн'!$J$44:$L$143)+SUMIF('Июл'!$E$44:$I$143,BM3,'Июл'!$J$44:$L$143)+SUMIF('Авг'!$E$44:$I$143,BM3,'Авг'!$J$44:$L$143)+SUMIF('Сен'!$E$44:$I$143,BM3,'Сен'!$J$44:$L$143)+SUMIF('Окт'!$E$44:$I$143,BM3,'Окт'!$J$44:$L$143) -> #N/A | BO3: ='Настройка'!B8 -> #REF! | BP3: =SUMIF('Ноя'!$W$44:$AA$143,BO3,'Ноя'!$AB$44:$AD$143)+SUMIF('Дек'!$W$44:$AA$143,BO3,'Дек'!$AB$44:$AD$143)+SUMIF('Янв'!$W$44:$AA$143,BO3,'Янв'!$AB$44:$AD$143)+SUMIF('Фев'!$W$44:$AA$143,BO3,'Фев'!$AB$44:$AD$143)+SUMIF('Мар'!$W$44:$AA$143,BO3,'Мар'!$AB$44:$AD$143)+SUMIF('Апр'!$W$44:$AA$143,BO3,'Апр'!$AB$44:$AD$143)+SUMIF('Май'!$W$44:$AA$143,BO3,'Май'!$AB$44:$AD$143)+SUMIF('Июн'!$W$44:$AA$143,BO3,'Июн'!$AB$44:$AD$143)+SUMIF('Июл'!$W$44:$AA$143,BO3,'Июл'!$AB$44:$AD$143)+SUMIF('Авг'!$W$44:$AA$143,BO3,'Авг'!$AB$44:$AD$143)+SUMIF('Сен'!$W$44:$AA$143,BO3,'Сен'!$AB$44:$AD$143)+SUMIF('Окт'!$W$44:$AA$143,BO3,'Окт'!$AB$44:$AD$143) -> #N/A
N4: =Nov!K5+Dec!K5+Jan!K5+Feb!K5+Mar!K5+Apr!K5+May!K5+Jun!K5+Jul!K5+Aug!K5+Sep!K5+Oct!K5 -> 0 | S4: =Nov!P5+Dec!P5+Jan!P5+Feb!P5+Mar!P5+Apr!P5+May!P5+Jun!P5+Jul!P5+Aug!P5+Sep!P5+Oct!P5 -> 0 | X4: =Nov!U5+Dec!U5+Jan!U5+Feb!U5+Mar!U5+Apr!U5+May!U5+Jun!U5+Jul!U5+Aug!U5+Sep!U5+Oct!U5 -> 0 | AR4: ='Настройка'!E11 -> #REF! | AV4: ='Настройка'!B11 -> #REF! | BA4: Расходы | BF4: =G40+SUM(AE28:AG39) -> 0 | BI4: =SUM(J44:L143) -> 0 | BM4: ='Настройка'!E9 -> #REF! | BN4: =SUMIF('Ноя'!$E$44:$I$143,BM4,'Ноя'!$J$44:$L$143)+SUMIF('Дек'!$E$44:$I$143,BM4,'Дек'!$J$44:$L$143)+SUMIF('Янв'!$E$44:$I$143,BM4,'Янв'!$J$44:$L$143)+SUMIF('Фев'!$E$44:$I$143,BM4,'Фев'!$J$44:$L$143)+SUMIF('Мар'!$E$44:$I$143,BM4,'Мар'!$J$44:$L$143)+SUMIF('Апр'!$E$44:$I$143,BM4,'Апр'!$J$44:$L$143)+SUMIF('Май'!$E$44:$I$143,BM4,'Май'!$J$44:$L$143)+SUMIF('Июн'!$E$44:$I$143,BM4,'Июн'!$J$44:$L$143)+SUMIF('Июл'!$E$44:$I$143,BM4,'Июл'!$J$44:$L$143)+SUMIF('Авг'!$E$44:$I$143,BM4,'Авг'!$J$44:$L$143)+SUMIF('Сен'!$E$44:$I$143,BM4,'Сен'!$J$44:$L$143)+SUMIF('Окт'!$E$44:$I$143,BM4,'Окт'!$J$44:$L$143) -> #N/A | BO4: ='Настройка'!B9 -> #REF! | BP4: =SUMIF('Ноя'!$W$44:$AA$143,BO4,'Ноя'!$AB$44:$AD$143)+SUMIF('Дек'!$W$44:$AA$143,BO4,'Дек'!$AB$44:$AD$143)+SUMIF('Янв'!$W$44:$AA$143,BO4,'Янв'!$AB$44:$AD$143)+SUMIF('Фев'!$W$44:$AA$143,BO4,'Фев'!$AB$44:$AD$143)+SUMIF('Мар'!$W$44:$AA$143,BO4,'Мар'!$AB$44:$AD$143)+SUMIF('Апр'!$W$44:$AA$143,BO4,'Апр'!$AB$44:$AD$143)+SUMIF('Май'!$W$44:$AA$143,BO4,'Май'!$AB$44:$AD$143)+SUMIF('Июн'!$W$44:$AA$143,BO4,'Июн'!$AB$44:$AD$143)+SUMIF('Июл'!$W$44:$AA$143,BO4,'Июл'!$AB$44:$AD$143)+SUMIF('Авг'!$W$44:$AA$143,BO4,'Авг'!$AB$44:$AD$143)+SUMIF('Сен'!$W$44:$AA$143,BO4,'Сен'!$AB$44:$AD$143)+SUMIF('Окт'!$W$44:$AA$143,BO4,'Окт'!$AB$44:$AD$143) -> #N/A
BA5: Остаток | BF5: =S40-G40-AE40 -> 0 | BI5: =SUM(AB44:AD143)-SUM(J44:L143) -> 0 | BM5: ='Настройка'!E10 -> #REF! | BN5: =SUMIF('Ноя'!$E$44:$I$143,BM5,'Ноя'!$J$44:$L$143)+SUMIF('Дек'!$E$44:$I$143,BM5,'Дек'!$J$44:$L$143)+SUMIF('Янв'!$E$44:$I$143,BM5,'Янв'!$J$44:$L$143)+SUMIF('Фев'!$E$44:$I$143,BM5,'Фев'!$J$44:$L$143)+SUMIF('Мар'!$E$44:$I$143,BM5,'Мар'!$J$44:$L$143)+SUMIF('Апр'!$E$44:$I$143,BM5,'Апр'!$J$44:$L$143)+SUMIF('Май'!$E$44:$I$143,BM5,'Май'!$J$44:$L$143)+SUMIF('Июн'!$E$44:$I$143,BM5,'Июн'!$J$44:$L$143)+SUMIF('Июл'!$E$44:$I$143,BM5,'Июл'!$J$44:$L$143)+SUMIF('Авг'!$E$44:$I$143,BM5,'Авг'!$J$44:$L$143)+SUMIF('Сен'!$E$44:$I$143,BM5,'Сен'!$J$44:$L$143)+SUMIF('Окт'!$E$44:$I$143,BM5,'Окт'!$J$44:$L$143) -> #N/A | BO5: ='Настройка'!B10 -> #REF! | BP5: =SUMIF('Ноя'!$W$44:$AA$143,BO5,'Ноя'!$AB$44:$AD$143)+SUMIF('Дек'!$W$44:$AA$143,BO5,'Дек'!$AB$44:$AD$143)+SUMIF('Янв'!$W$44:$AA$143,BO5,'Янв'!$AB$44:$AD$143)+SUMIF('Фев'!$W$44:$AA$143,BO5,'Фев'!$AB$44:$AD$143)+SUMIF('Мар'!$W$44:$AA$143,BO5,'Мар'!$AB$44:$AD$143)+SUMIF('Апр'!$W$44:$AA$143,BO5,'Апр'!$AB$44:$AD$143)+SUMIF('Май'!$W$44:$AA$143,BO5,'Май'!$AB$44:$AD$143)+SUMIF('Июн'!$W$44:$AA$143,BO5,'Июн'!$AB$44:$AD$143)+SUMIF('Июл'!$W$44:$AA$143,BO5,'Июл'!$AB$44:$AD$143)+SUMIF('Авг'!$W$44:$AA$143,BO5,'Авг'!$AB$44:$AD$143)+SUMIF('Сен'!$W$44:$AA$143,BO5,'Сен'!$AB$44:$AD$143)+SUMIF('Окт'!$W$44:$AA$143,BO5,'Окт'!$AB$44:$AD$143) -> #N/A
BA6: Общий остаток | BF6: =F5+BF5 -> 0 | BI6: =F5+BI5 -> 0 | BM6: ='Настройка'!E11 -> #REF! | BN6: =SUMIF('Ноя'!$E$44:$I$143,BM6,'Ноя'!$J$44:$L$143)+SUMIF('Дек'!$E$44:$I$143,BM6,'Дек'!$J$44:$L$143)+SUMIF('Янв'!$E$44:$I$143,BM6,'Янв'!$J$44:$L$143)+SUMIF('Фев'!$E$44:$I$143,BM6,'Фев'!$J$44:$L$143)+SUMIF('Мар'!$E$44:$I$143,BM6,'Мар'!$J$44:$L$143)+SUMIF('Апр'!$E$44:$I$143,BM6,'Апр'!$J$44:$L$143)+SUMIF('Май'!$E$44:$I$143,BM6,'Май'!$J$44:$L$143)+SUMIF('Июн'!$E$44:$I$143,BM6,'Июн'!$J$44:$L$143)+SUMIF('Июл'!$E$44:$I$143,BM6,'Июл'!$J$44:$L$143)+SUMIF('Авг'!$E$44:$I$143,BM6,'Авг'!$J$44:$L$143)+SUMIF('Сен'!$E$44:$I$143,BM6,'Сен'!$J$44:$L$143)+SUMIF('Окт'!$E$44:$I$143,BM6,'Окт'!$J$44:$L$143) -> #N/A | BO6: ='Настройка'!B11 -> #REF! | BP6: =SUMIF('Ноя'!$W$44:$AA$143,BO6,'Ноя'!$AB$44:$AD$143)+SUMIF('Дек'!$W$44:$AA$143,BO6,'Дек'!$AB$44:$AD$143)+SUMIF('Янв'!$W$44:$AA$143,BO6,'Янв'!$AB$44:$AD$143)+SUMIF('Фев'!$W$44:$AA$143,BO6,'Фев'!$AB$44:$AD$143)+SUMIF('Мар'!$W$44:$AA$143,BO6,'Мар'!$AB$44:$AD$143)+SUMIF('Апр'!$W$44:$AA$143,BO6,'Апр'!$AB$44:$AD$143)+SUMIF('Май'!$W$44:$AA$143,BO6,'Май'!$AB$44:$AD$143)+SUMIF('Июн'!$W$44:$AA$143,BO6,'Июн'!$AB$44:$AD$143)+SUMIF('Июл'!$W$44:$AA$143,BO6,'Июл'!$AB$44:$AD$143)+SUMIF('Авг'!$W$44:$AA$143,BO6,'Авг'!$AB$44:$AD$143)+SUMIF('Сен'!$W$44:$AA$143,BO6,'Сен'!$AB$44:$AD$143)+SUMIF('Окт'!$W$44:$AA$143,BO6,'Окт'!$AB$44:$AD$143) -> #N/A
BA7: Долги | BF7: =AE40 | BM7: ='Настройка'!E12 -> #REF! | BN7: =SUMIF('Ноя'!$E$44:$I$143,BM7,'Ноя'!$J$44:$L$143)+SUMIF('Дек'!$E$44:$I$143,BM7,'Дек'!$J$44:$L$143)+SUMIF('Янв'!$E$44:$I$143,BM7,'Янв'!$J$44:$L$143)+SUMIF('Фев'!$E$44:$I$143,BM7,'Фев'!$J$44:$L$143)+SUMIF('Мар'!$E$44:$I$143,BM7,'Мар'!$J$44:$L$143)+SUMIF('Апр'!$E$44:$I$143,BM7,'Апр'!$J$44:$L$143)+SUMIF('Май'!$E$44:$I$143,BM7,'Май'!$J$44:$L$143)+SUMIF('Июн'!$E$44:$I$143,BM7,'Июн'!$J$44:$L$143)+SUMIF('Июл'!$E$44:$I$143,BM7,'Июл'!$J$44:$L$143)+SUMIF('Авг'!$E$44:$I$143,BM7,'Авг'!$J$44:$L$143)+SUMIF('Сен'!$E$44:$I$143,BM7,'Сен'!$J$44:$L$143)+SUMIF('Окт'!$E$44:$I$143,BM7,'Окт'!$J$44:$L$143) -> #N/A | BO7: ='Настройка'!B12 -> #REF! | BP7: =SUMIF('Ноя'!$W$44:$AA$143,BO7,'Ноя'!$AB$44:$AD$143)+SUMIF('Дек'!$W$44:$AA$143,BO7,'Дек'!$AB$44:$AD$143)+SUMIF('Янв'!$W$44:$AA$143,BO7,'Янв'!$AB$44:$AD$143)+SUMIF('Фев'!$W$44:$AA$143,BO7,'Фев'!$AB$44:$AD$143)+SUMIF('Мар'!$W$44:$AA$143,BO7,'Мар'!$AB$44:$AD$143)+SUMIF('Апр'!$W$44:$AA$143,BO7,'Апр'!$AB$44:$AD$143)+SUMIF('Май'!$W$44:$AA$143,BO7,'Май'!$AB$44:$AD$143)+SUMIF('Июн'!$W$44:$AA$143,BO7,'Июн'!$AB$44:$AD$143)+SUMIF('Июл'!$W$44:$AA$143,BO7,'Июл'!$AB$44:$AD$143)+SUMIF('Авг'!$W$44:$AA$143,BO7,'Авг'!$AB$44:$AD$143)+SUMIF('Сен'!$W$44:$AA$143,BO7,'Сен'!$AB$44:$AD$143)+SUMIF('Окт'!$W$44:$AA$143,BO7,'Окт'!$AB$44:$AD$143) -> #N/A
B8: ხარჯები კატეგორიის მიხედვით | N8: გეგმა / რეალობა | Z8: შემოსავალი კატეგორიის მიხედვით | BA8: Тренд расходов | BF8: 0 | BM8: ='Настройка'!E13 -> #REF! | BN8: =SUMIF('Ноя'!$E$44:$I$143,BM8,'Ноя'!$J$44:$L$143)+SUMIF('Дек'!$E$44:$I$143,BM8,'Дек'!$J$44:$L$143)+SUMIF('Янв'!$E$44:$I$143,BM8,'Янв'!$J$44:$L$143)+SUMIF('Фев'!$E$44:$I$143,BM8,'Фев'!$J$44:$L$143)+SUMIF('Мар'!$E$44:$I$143,BM8,'Мар'!$J$44:$L$143)+SUMIF('Апр'!$E$44:$I$143,BM8,'Апр'!$J$44:$L$143)+SUMIF('Май'!$E$44:$I$143,BM8,'Май'!$J$44:$L$143)+SUMIF('Июн'!$E$44:$I$143,BM8,'Июн'!$J$44:$L$143)+SUMIF('Июл'!$E$44:$I$143,BM8,'Июл'!$J$44:$L$143)+SUMIF('Авг'!$E$44:$I$143,BM8,'Авг'!$J$44:$L$143)+SUMIF('Сен'!$E$44:$I$143,BM8,'Сен'!$J$44:$L$143)+SUMIF('Окт'!$E$44:$I$143,BM8,'Окт'!$J$44:$L$143) -> #N/A | BO8: ='Настройка'!B13 -> #REF! | BP8: =SUMIF('Ноя'!$W$44:$AA$143,BO8,'Ноя'!$AB$44:$AD$143)+SUMIF('Дек'!$W$44:$AA$143,BO8,'Дек'!$AB$44:$AD$143)+SUMIF('Янв'!$W$44:$AA$143,BO8,'Янв'!$AB$44:$AD$143)+SUMIF('Фев'!$W$44:$AA$143,BO8,'Фев'!$AB$44:$AD$143)+SUMIF('Мар'!$W$44:$AA$143,BO8,'Мар'!$AB$44:$AD$143)+SUMIF('Апр'!$W$44:$AA$143,BO8,'Апр'!$AB$44:$AD$143)+SUMIF('Май'!$W$44:$AA$143,BO8,'Май'!$AB$44:$AD$143)+SUMIF('Июн'!$W$44:$AA$143,BO8,'Июн'!$AB$44:$AD$143)+SUMIF('Июл'!$W$44:$AA$143,BO8,'Июл'!$AB$44:$AD$143)+SUMIF('Авг'!$W$44:$AA$143,BO8,'Авг'!$AB$44:$AD$143)+SUMIF('Сен'!$W$44:$AA$143,BO8,'Сен'!$AB$44:$AD$143)+SUMIF('Окт'!$W$44:$AA$143,BO8,'Окт'!$AB$44:$AD$143) -> #N/A
AR9: ='Настройка'!E12 -> #REF! | AV9: ='Настройка'!B12 -> #REF! | BA9: Тренд доходов | BF9: 0 | BM9: ='Настройка'!E14 -> #REF! | BN9: =SUMIF('Ноя'!$E$44:$I$143,BM9,'Ноя'!$J$44:$L$143)+SUMIF('Дек'!$E$44:$I$143,BM9,'Дек'!$J$44:$L$143)+SUMIF('Янв'!$E$44:$I$143,BM9,'Янв'!$J$44:$L$143)+SUMIF('Фев'!$E$44:$I$143,BM9,'Фев'!$J$44:$L$143)+SUMIF('Мар'!$E$44:$I$143,BM9,'Мар'!$J$44:$L$143)+SUMIF('Апр'!$E$44:$I$143,BM9,'Апр'!$J$44:$L$143)+SUMIF('Май'!$E$44:$I$143,BM9,'Май'!$J$44:$L$143)+SUMIF('Июн'!$E$44:$I$143,BM9,'Июн'!$J$44:$L$143)+SUMIF('Июл'!$E$44:$I$143,BM9,'Июл'!$J$44:$L$143)+SUMIF('Авг'!$E$44:$I$143,BM9,'Авг'!$J$44:$L$143)+SUMIF('Сен'!$E$44:$I$143,BM9,'Сен'!$J$44:$L$143)+SUMIF('Окт'!$E$44:$I$143,BM9,'Окт'!$J$44:$L$143) -> #N/A | BO9: ='Настройка'!B14 -> #REF! | BP9: =SUMIF('Ноя'!$W$44:$AA$143,BO9,'Ноя'!$AB$44:$AD$143)+SUMIF('Дек'!$W$44:$AA$143,BO9,'Дек'!$AB$44:$AD$143)+SUMIF('Янв'!$W$44:$AA$143,BO9,'Янв'!$AB$44:$AD$143)+SUMIF('Фев'!$W$44:$AA$143,BO9,'Фев'!$AB$44:$AD$143)+SUMIF('Мар'!$W$44:$AA$143,BO9,'Мар'!$AB$44:$AD$143)+SUMIF('Апр'!$W$44:$AA$143,BO9,'Апр'!$AB$44:$AD$143)+SUMIF('Май'!$W$44:$AA$143,BO9,'Май'!$AB$44:$AD$143)+SUMIF('Июн'!$W$44:$AA$143,BO9,'Июн'!$AB$44:$AD$143)+SUMIF('Июл'!$W$44:$AA$143,BO9,'Июл'!$AB$44:$AD$143)+SUMIF('Авг'!$W$44:$AA$143,BO9,'Авг'!$AB$44:$AD$143)+SUMIF('Сен'!$W$44:$AA$143,BO9,'Сен'!$AB$44:$AD$143)+SUMIF('Окт'!$W$44:$AA$143,BO9,'Окт'!$AB$44:$AD$143) -> #N/A
AR10: ='Настройка'!E13 -> #REF! | AV10: ='Настройка'!B13 -> #REF! | BM10: ='Настройка'!E15 -> #REF! | BN10: =SUMIF('Ноя'!$E$44:$I$143,BM10,'Ноя'!$J$44:$L$143)+SUMIF('Дек'!$E$44:$I$143,BM10,'Дек'!$J$44:$L$143)+SUMIF('Янв'!$E$44:$I$143,BM10,'Янв'!$J$44:$L$143)+SUMIF('Фев'!$E$44:$I$143,BM10,'Фев'!$J$44:$L$143)+SUMIF('Мар'!$E$44:$I$143,BM10,'Мар'!$J$44:$L$143)+SUMIF('Апр'!$E$44:$I$143,BM10,'Апр'!$J$44:$L$143)+SUMIF('Май'!$E$44:$I$143,BM10,'Май'!$J$44:$L$143)+SUMIF('Июн'!$E$44:$I$143,BM10,'Июн'!$J$44:$L$143)+SUMIF('Июл'!$E$44:$I$143,BM10,'Июл'!$J$44:$L$143)+SUMIF('Авг'!$E$44:$I$143,BM10,'Авг'!$J$44:$L$143)+SUMIF('Сен'!$E$44:$I$143,BM10,'Сен'!$J$44:$L$143)+SUMIF('Окт'!$E$44:$I$143,BM10,'Окт'!$J$44:$L$143) -> #N/A | BO10: ='Настройка'!B15 -> #REF! | BP10: =SUMIF('Ноя'!$W$44:$AA$143,BO10,'Ноя'!$AB$44:$AD$143)+SUMIF('Дек'!$W$44:$AA$143,BO10,'Дек'!$AB$44:$AD$143)+SUMIF('Янв'!$W$44:$AA$143,BO10,'Янв'!$AB$44:$AD$143)+SUMIF('Фев'!$W$44:$AA$143,BO10,'Фев'!$AB$44:$AD$143)+SUMIF('Мар'!$W$44:$AA$143,BO10,'Мар'!$AB$44:$AD$143)+SUMIF('Апр'!$W$44:$AA$143,BO10,'Апр'!$AB$44:$AD$143)+SUMIF('Май'!$W$44:$AA$143,BO10,'Май'!$AB$44:$AD$143)+SUMIF('Июн'!$W$44:$AA$143,BO10,'Июн'!$AB$44:$AD$143)+SUMIF('Июл'!$W$44:$AA$143,BO10,'Июл'!$AB$44:$AD$143)+SUMIF('Авг'!$W$44:$AA$143,BO10,'Авг'!$AB$44:$AD$143)+SUMIF('Сен'!$W$44:$AA$143,BO10,'Сен'!$AB$44:$AD$143)+SUMIF('Окт'!$W$44:$AA$143,BO10,'Окт'!$AB$44:$AD$143) -> #N/A
AR11: ='Настройка'!E14 -> #REF! | AV11: ='Настройка'!B14 -> #REF! | BM11: ='Настройка'!E16 -> #REF! | BN11: =SUMIF('Ноя'!$E$44:$I$143,BM11,'Ноя'!$J$44:$L$143)+SUMIF('Дек'!$E$44:$I$143,BM11,'Дек'!$J$44:$L$143)+SUMIF('Янв'!$E$44:$I$143,BM11,'Янв'!$J$44:$L$143)+SUMIF('Фев'!$E$44:$I$143,BM11,'Фев'!$J$44:$L$143)+SUMIF('Мар'!$E$44:$I$143,BM11,'Мар'!$J$44:$L$143)+SUMIF('Апр'!$E$44:$I$143,BM11,'Апр'!$J$44:$L$143)+SUMIF('Май'!$E$44:$I$143,BM11,'Май'!$J$44:$L$143)+SUMIF('Июн'!$E$44:$I$143,BM11,'Июн'!$J$44:$L$143)+SUMIF('Июл'!$E$44:$I$143,BM11,'Июл'!$J$44:$L$143)+SUMIF('Авг'!$E$44:$I$143,BM11,'Авг'!$J$44:$L$143)+SUMIF('Сен'!$E$44:$I$143,BM11,'Сен'!$J$44:$L$143)+SUMIF('Окт'!$E$44:$I$143,BM11,'Окт'!$J$44:$L$143) -> #N/A | BO11: ='Настройка'!B16 -> #REF! | BP11: =SUMIF('Ноя'!$W$44:$AA$143,BO11,'Ноя'!$AB$44:$AD$143)+SUMIF('Дек'!$W$44:$AA$143,BO11,'Дек'!$AB$44:$AD$143)+SUMIF('Янв'!$W$44:$AA$143,BO11,'Янв'!$AB$44:$AD$143)+SUMIF('Фев'!$W$44:$AA$143,BO11,'Фев'!$AB$44:$AD$143)+SUMIF('Мар'!$W$44:$AA$143,BO11,'Мар'!$AB$44:$AD$143)+SUMIF('Апр'!$W$44:$AA$143,BO11,'Апр'!$AB$44:$AD$143)+SUMIF('Май'!$W$44:$AA$143,BO11,'Май'!$AB$44:$AD$143)+SUMIF('Июн'!$W$44:$AA$143,BO11,'Июн'!$AB$44:$AD$143)+SUMIF('Июл'!$W$44:$AA$143,BO11,'Июл'!$AB$44:$AD$143)+SUMIF('Авг'!$W$44:$AA$143,BO11,'Авг'!$AB$44:$AD$143)+SUMIF('Сен'!$W$44:$AA$143,BO11,'Сен'!$AB$44:$AD$143)+SUMIF('Окт'!$W$44:$AA$143,BO11,'Окт'!$AB$44:$AD$143) -> #N/A
AR12: ='Настройка'!E15 -> #REF! | AV12: ='Настройка'!B15 -> #REF! | BM12: ='Настройка'!E17 -> #REF! | BN12: =SUMIF('Ноя'!$E$44:$I$143,BM12,'Ноя'!$J$44:$L$143)+SUMIF('Дек'!$E$44:$I$143,BM12,'Дек'!$J$44:$L$143)+SUMIF('Янв'!$E$44:$I$143,BM12,'Янв'!$J$44:$L$143)+SUMIF('Фев'!$E$44:$I$143,BM12,'Фев'!$J$44:$L$143)+SUMIF('Мар'!$E$44:$I$143,BM12,'Мар'!$J$44:$L$143)+SUMIF('Апр'!$E$44:$I$143,BM12,'Апр'!$J$44:$L$143)+SUMIF('Май'!$E$44:$I$143,BM12,'Май'!$J$44:$L$143)+SUMIF('Июн'!$E$44:$I$143,BM12,'Июн'!$J$44:$L$143)+SUMIF('Июл'!$E$44:$I$143,BM12,'Июл'!$J$44:$L$143)+SUMIF('Авг'!$E$44:$I$143,BM12,'Авг'!$J$44:$L$143)+SUMIF('Сен'!$E$44:$I$143,BM12,'Сен'!$J$44:$L$143)+SUMIF('Окт'!$E$44:$I$143,BM12,'Окт'!$J$44:$L$143) -> #N/A | BO12: ='Настройка'!B17 -> #REF! | BP12: =SUMIF('Ноя'!$W$44:$AA$143,BO12,'Ноя'!$AB$44:$AD$143)+SUMIF('Дек'!$W$44:$AA$143,BO12,'Дек'!$AB$44:$AD$143)+SUMIF('Янв'!$W$44:$AA$143,BO12,'Янв'!$AB$44:$AD$143)+SUMIF('Фев'!$W$44:$AA$143,BO12,'Фев'!$AB$44:$AD$143)+SUMIF('Мар'!$W$44:$AA$143,BO12,'Мар'!$AB$44:$AD$143)+SUMIF('Апр'!$W$44:$AA$143,BO12,'Апр'!$AB$44:$AD$143)+SUMIF('Май'!$W$44:$AA$143,BO12,'Май'!$AB$44:$AD$143)+SUMIF('Июн'!$W$44:$AA$143,BO12,'Июн'!$AB$44:$AD$143)+SUMIF('Июл'!$W$44:$AA$143,BO12,'Июл'!$AB$44:$AD$143)+SUMIF('Авг'!$W$44:$AA$143,BO12,'Авг'!$AB$44:$AD$143)+SUMIF('Сен'!$W$44:$AA$143,BO12,'Сен'!$AB$44:$AD$143)+SUMIF('Окт'!$W$44:$AA$143,BO12,'Окт'!$AB$44:$AD$143) -> #N/A
AR13: ='Настройка'!E16 -> #REF! | AV13: ='Настройка'!B16 -> #REF! | BM13: ='Настройка'!E18 -> #REF! | BN13: =SUMIF('Ноя'!$E$44:$I$143,BM13,'Ноя'!$J$44:$L$143)+SUMIF('Дек'!$E$44:$I$143,BM13,'Дек'!$J$44:$L$143)+SUMIF('Янв'!$E$44:$I$143,BM13,'Янв'!$J$44:$L$143)+SUMIF('Фев'!$E$44:$I$143,BM13,'Фев'!$J$44:$L$143)+SUMIF('Мар'!$E$44:$I$143,BM13,'Мар'!$J$44:$L$143)+SUMIF('Апр'!$E$44:$I$143,BM13,'Апр'!$J$44:$L$143)+SUMIF('Май'!$E$44:$I$143,BM13,'Май'!$J$44:$L$143)+SUMIF('Июн'!$E$44:$I$143,BM13,'Июн'!$J$44:$L$143)+SUMIF('Июл'!$E$44:$I$143,BM13,'Июл'!$J$44:$L$143)+SUMIF('Авг'!$E$44:$I$143,BM13,'Авг'!$J$44:$L$143)+SUMIF('Сен'!$E$44:$I$143,BM13,'Сен'!$J$44:$L$143)+SUMIF('Окт'!$E$44:$I$143,BM13,'Окт'!$J$44:$L$143) -> #N/A | BO13: ='Настройка'!B18 -> #REF! | BP13: =SUMIF('Ноя'!$W$44:$AA$143,BO13,'Ноя'!$AB$44:$AD$143)+SUMIF('Дек'!$W$44:$AA$143,BO13,'Дек'!$AB$44:$AD$143)+SUMIF('Янв'!$W$44:$AA$143,BO13,'Янв'!$AB$44:$AD$143)+SUMIF('Фев'!$W$44:$AA$143,BO13,'Фев'!$AB$44:$AD$143)+SUMIF('Мар'!$W$44:$AA$143,BO13,'Мар'!$AB$44:$AD$143)+SUMIF('Апр'!$W$44:$AA$143,BO13,'Апр'!$AB$44:$AD$143)+SUMIF('Май'!$W$44:$AA$143,BO13,'Май'!$AB$44:$AD$143)+SUMIF('Июн'!$W$44:$AA$143,BO13,'Июн'!$AB$44:$AD$143)+SUMIF('Июл'!$W$44:$AA$143,BO13,'Июл'!$AB$44:$AD$143)+SUMIF('Авг'!$W$44:$AA$143,BO13,'Авг'!$AB$44:$AD$143)+SUMIF('Сен'!$W$44:$AA$143,BO13,'Сен'!$AB$44:$AD$143)+SUMIF('Окт'!$W$44:$AA$143,BO13,'Окт'!$AB$44:$AD$143) -> #N/A
AR14: ='Настройка'!E17 -> #REF! | AV14: ='Настройка'!B17 -> #REF! | BM14: ='Настройка'!E19 -> #REF! | BN14: =SUMIF('Ноя'!$E$44:$I$143,BM14,'Ноя'!$J$44:$L$143)+SUMIF('Дек'!$E$44:$I$143,BM14,'Дек'!$J$44:$L$143)+SUMIF('Янв'!$E$44:$I$143,BM14,'Янв'!$J$44:$L$143)+SUMIF('Фев'!$E$44:$I$143,BM14,'Фев'!$J$44:$L$143)+SUMIF('Мар'!$E$44:$I$143,BM14,'Мар'!$J$44:$L$143)+SUMIF('Апр'!$E$44:$I$143,BM14,'Апр'!$J$44:$L$143)+SUMIF('Май'!$E$44:$I$143,BM14,'Май'!$J$44:$L$143)+SUMIF('Июн'!$E$44:$I$143,BM14,'Июн'!$J$44:$L$143)+SUMIF('Июл'!$E$44:$I$143,BM14,'Июл'!$J$44:$L$143)+SUMIF('Авг'!$E$44:$I$143,BM14,'Авг'!$J$44:$L$143)+SUMIF('Сен'!$E$44:$I$143,BM14,'Сен'!$J$44:$L$143)+SUMIF('Окт'!$E$44:$I$143,BM14,'Окт'!$J$44:$L$143) -> #N/A | BO14: ='Настройка'!B19 -> #REF! | BP14: =SUMIF('Ноя'!$W$44:$AA$143,BO14,'Ноя'!$AB$44:$AD$143)+SUMIF('Дек'!$W$44:$AA$143,BO14,'Дек'!$AB$44:$AD$143)+SUMIF('Янв'!$W$44:$AA$143,BO14,'Янв'!$AB$44:$AD$143)+SUMIF('Фев'!$W$44:$AA$143,BO14,'Фев'!$AB$44:$AD$143)+SUMIF('Мар'!$W$44:$AA$143,BO14,'Мар'!$AB$44:$AD$143)+SUMIF('Апр'!$W$44:$AA$143,BO14,'Апр'!$AB$44:$AD$143)+SUMIF('Май'!$W$44:$AA$143,BO14,'Май'!$AB$44:$AD$143)+SUMIF('Июн'!$W$44:$AA$143,BO14,'Июн'!$AB$44:$AD$143)+SUMIF('Июл'!$W$44:$AA$143,BO14,'Июл'!$AB$44:$AD$143)+SUMIF('Авг'!$W$44:$AA$143,BO14,'Авг'!$AB$44:$AD$143)+SUMIF('Сен'!$W$44:$AA$143,BO14,'Сен'!$AB$44:$AD$143)+SUMIF('Окт'!$W$44:$AA$143,BO14,'Окт'!$AB$44:$AD$143) -> #N/A
AR15: ='Настройка'!E18 -> #REF! | AV15: ='Настройка'!B18 -> #REF! | BM15: ='Настройка'!E20 -> #REF! | BN15: =SUMIF('Ноя'!$E$44:$I$143,BM15,'Ноя'!$J$44:$L$143)+SUMIF('Дек'!$E$44:$I$143,BM15,'Дек'!$J$44:$L$143)+SUMIF('Янв'!$E$44:$I$143,BM15,'Янв'!$J$44:$L$143)+SUMIF('Фев'!$E$44:$I$143,BM15,'Фев'!$J$44:$L$143)+SUMIF('Мар'!$E$44:$I$143,BM15,'Мар'!$J$44:$L$143)+SUMIF('Апр'!$E$44:$I$143,BM15,'Апр'!$J$44:$L$143)+SUMIF('Май'!$E$44:$I$143,BM15,'Май'!$J$44:$L$143)+SUMIF('Июн'!$E$44:$I$143,BM15,'Июн'!$J$44:$L$143)+SUMIF('Июл'!$E$44:$I$143,BM15,'Июл'!$J$44:$L$143)+SUMIF('Авг'!$E$44:$I$143,BM15,'Авг'!$J$44:$L$143)+SUMIF('Сен'!$E$44:$I$143,BM15,'Сен'!$J$44:$L$143)+SUMIF('Окт'!$E$44:$I$143,BM15,'Окт'!$J$44:$L$143) -> #N/A | BO15: ='Настройка'!B20 -> #REF! | BP15: =SUMIF('Ноя'!$W$44:$AA$143,BO15,'Ноя'!$AB$44:$AD$143)+SUMIF('Дек'!$W$44:$AA$143,BO15,'Дек'!$AB$44:$AD$143)+SUMIF('Янв'!$W$44:$AA$143,BO15,'Янв'!$AB$44:$AD$143)+SUMIF('Фев'!$W$44:$AA$143,BO15,'Фев'!$AB$44:$AD$143)+SUMIF('Мар'!$W$44:$AA$143,BO15,'Мар'!$AB$44:$AD$143)+SUMIF('Апр'!$W$44:$AA$143,BO15,'Апр'!$AB$44:$AD$143)+SUMIF('Май'!$W$44:$AA$143,BO15,'Май'!$AB$44:$AD$143)+SUMIF('Июн'!$W$44:$AA$143,BO15,'Июн'!$AB$44:$AD$143)+SUMIF('Июл'!$W$44:$AA$143,BO15,'Июл'!$AB$44:$AD$143)+SUMIF('Авг'!$W$44:$AA$143,BO15,'Авг'!$AB$44:$AD$143)+SUMIF('Сен'!$W$44:$AA$143,BO15,'Сен'!$AB$44:$AD$143)+SUMIF('Окт'!$W$44:$AA$143,BO15,'Окт'!$AB$44:$AD$143) -> #N/A
AR16: ='Настройка'!E19 -> #REF! | AV16: ='Настройка'!B19 -> #REF! | BM16: ='Настройка'!E21 -> #REF! | BN16: =SUMIF('Ноя'!$E$44:$I$143,BM16,'Ноя'!$J$44:$L$143)+SUMIF('Дек'!$E$44:$I$143,BM16,'Дек'!$J$44:$L$143)+SUMIF('Янв'!$E$44:$I$143,BM16,'Янв'!$J$44:$L$143)+SUMIF('Фев'!$E$44:$I$143,BM16,'Фев'!$J$44:$L$143)+SUMIF('Мар'!$E$44:$I$143,BM16,'Мар'!$J$44:$L$143)+SUMIF('Апр'!$E$44:$I$143,BM16,'Апр'!$J$44:$L$143)+SUMIF('Май'!$E$44:$I$143,BM16,'Май'!$J$44:$L$143)+SUMIF('Июн'!$E$44:$I$143,BM16,'Июн'!$J$44:$L$143)+SUMIF('Июл'!$E$44:$I$143,BM16,'Июл'!$J$44:$L$143)+SUMIF('Авг'!$E$44:$I$143,BM16,'Авг'!$J$44:$L$143)+SUMIF('Сен'!$E$44:$I$143,BM16,'Сен'!$J$44:$L$143)+SUMIF('Окт'!$E$44:$I$143,BM16,'Окт'!$J$44:$L$143) -> #N/A | BO16: ='Настройка'!B21 -> #REF! | BP16: =SUMIF('Ноя'!$W$44:$AA$143,BO16,'Ноя'!$AB$44:$AD$143)+SUMIF('Дек'!$W$44:$AA$143,BO16,'Дек'!$AB$44:$AD$143)+SUMIF('Янв'!$W$44:$AA$143,BO16,'Янв'!$AB$44:$AD$143)+SUMIF('Фев'!$W$44:$AA$143,BO16,'Фев'!$AB$44:$AD$143)+SUMIF('Мар'!$W$44:$AA$143,BO16,'Мар'!$AB$44:$AD$143)+SUMIF('Апр'!$W$44:$AA$143,BO16,'Апр'!$AB$44:$AD$143)+SUMIF('Май'!$W$44:$AA$143,BO16,'Май'!$AB$44:$AD$143)+SUMIF('Июн'!$W$44:$AA$143,BO16,'Июн'!$AB$44:$AD$143)+SUMIF('Июл'!$W$44:$AA$143,BO16,'Июл'!$AB$44:$AD$143)+SUMIF('Авг'!$W$44:$AA$143,BO16,'Авг'!$AB$44:$AD$143)+SUMIF('Сен'!$W$44:$AA$143,BO16,'Сен'!$AB$44:$AD$143)+SUMIF('Окт'!$W$44:$AA$143,BO16,'Окт'!$AB$44:$AD$143) -> #N/A
AR17: ='Настройка'!E20 -> #REF! | AV17: ='Настройка'!B20 -> #REF! | BM17: ='Настройка'!E22 -> #REF! | BN17: =SUMIF('Ноя'!$E$44:$I$143,BM17,'Ноя'!$J$44:$L$143)+SUMIF('Дек'!$E$44:$I$143,BM17,'Дек'!$J$44:$L$143)+SUMIF('Янв'!$E$44:$I$143,BM17,'Янв'!$J$44:$L$143)+SUMIF('Фев'!$E$44:$I$143,BM17,'Фев'!$J$44:$L$143)+SUMIF('Мар'!$E$44:$I$143,BM17,'Мар'!$J$44:$L$143)+SUMIF('Апр'!$E$44:$I$143,BM17,'Апр'!$J$44:$L$143)+SUMIF('Май'!$E$44:$I$143,BM17,'Май'!$J$44:$L$143)+SUMIF('Июн'!$E$44:$I$143,BM17,'Июн'!$J$44:$L$143)+SUMIF('Июл'!$E$44:$I$143,BM17,'Июл'!$J$44:$L$143)+SUMIF('Авг'!$E$44:$I$143,BM17,'Авг'!$J$44:$L$143)+SUMIF('Сен'!$E$44:$I$143,BM17,'Сен'!$J$44:$L$143)+SUMIF('Окт'!$E$44:$I$143,BM17,'Окт'!$J$44:$L$143) -> #N/A | BO17: ='Настройка'!B22 -> #REF! | BP17: =SUMIF('Ноя'!$W$44:$AA$143,BO17,'Ноя'!$AB$44:$AD$143)+SUMIF('Дек'!$W$44:$AA$143,BO17,'Дек'!$AB$44:$AD$143)+SUMIF('Янв'!$W$44:$AA$143,BO17,'Янв'!$AB$44:$AD$143)+SUMIF('Фев'!$W$44:$AA$143,BO17,'Фев'!$AB$44:$AD$143)+SUMIF('Мар'!$W$44:$AA$143,BO17,'Мар'!$AB$44:$AD$143)+SUMIF('Апр'!$W$44:$AA$143,BO17,'Апр'!$AB$44:$AD$143)+SUMIF('Май'!$W$44:$AA$143,BO17,'Май'!$AB$44:$AD$143)+SUMIF('Июн'!$W$44:$AA$143,BO17,'Июн'!$AB$44:$AD$143)+SUMIF('Июл'!$W$44:$AA$143,BO17,'Июл'!$AB$44:$AD$143)+SUMIF('Авг'!$W$44:$AA$143,BO17,'Авг'!$AB$44:$AD$143)+SUMIF('Сен'!$W$44:$AA$143,BO17,'Сен'!$AB$44:$AD$143)+SUMIF('Окт'!$W$44:$AA$143,BO17,'Окт'!$AB$44:$AD$143) -> #N/A
AR18: ='Настройка'!E21 -> #REF! | AV18: ='Настройка'!B21 -> #REF! | BM18: ='Настройка'!E23 -> #REF! | BN18: =SUMIF('Ноя'!$E$44:$I$143,BM18,'Ноя'!$J$44:$L$143)+SUMIF('Дек'!$E$44:$I$143,BM18,'Дек'!$J$44:$L$143)+SUMIF('Янв'!$E$44:$I$143,BM18,'Янв'!$J$44:$L$143)+SUMIF('Фев'!$E$44:$I$143,BM18,'Фев'!$J$44:$L$143)+SUMIF('Мар'!$E$44:$I$143,BM18,'Мар'!$J$44:$L$143)+SUMIF('Апр'!$E$44:$I$143,BM18,'Апр'!$J$44:$L$143)+SUMIF('Май'!$E$44:$I$143,BM18,'Май'!$J$44:$L$143)+SUMIF('Июн'!$E$44:$I$143,BM18,'Июн'!$J$44:$L$143)+SUMIF('Июл'!$E$44:$I$143,BM18,'Июл'!$J$44:$L$143)+SUMIF('Авг'!$E$44:$I$143,BM18,'Авг'!$J$44:$L$143)+SUMIF('Сен'!$E$44:$I$143,BM18,'Сен'!$J$44:$L$143)+SUMIF('Окт'!$E$44:$I$143,BM18,'Окт'!$J$44:$L$143) -> #N/A | BO18: ='Настройка'!B23 -> #REF! | BP18: =SUMIF('Ноя'!$W$44:$AA$143,BO18,'Ноя'!$AB$44:$AD$143)+SUMIF('Дек'!$W$44:$AA$143,BO18,'Дек'!$AB$44:$AD$143)+SUMIF('Янв'!$W$44:$AA$143,BO18,'Янв'!$AB$44:$AD$143)+SUMIF('Фев'!$W$44:$AA$143,BO18,'Фев'!$AB$44:$AD$143)+SUMIF('Мар'!$W$44:$AA$143,BO18,'Мар'!$AB$44:$AD$143)+SUMIF('Апр'!$W$44:$AA$143,BO18,'Апр'!$AB$44:$AD$143)+SUMIF('Май'!$W$44:$AA$143,BO18,'Май'!$AB$44:$AD$143)+SUMIF('Июн'!$W$44:$AA$143,BO18,'Июн'!$AB$44:$AD$143)+SUMIF('Июл'!$W$44:$AA$143,BO18,'Июл'!$AB$44:$AD$143)+SUMIF('Авг'!$W$44:$AA$143,BO18,'Авг'!$AB$44:$AD$143)+SUMIF('Сен'!$W$44:$AA$143,BO18,'Сен'!$AB$44:$AD$143)+SUMIF('Окт'!$W$44:$AA$143,BO18,'Окт'!$AB$44:$AD$143) -> #N/A
AR19: ='Настройка'!E22 -> #REF! | AV19: ='Настройка'!B22 -> #REF! | AZ19: ='Настройка'!B21 -> #REF! | BM19: ='Настройка'!E24 -> #REF! | BN19: =SUMIF('Ноя'!$E$44:$I$143,BM19,'Ноя'!$J$44:$L$143)+SUMIF('Дек'!$E$44:$I$143,BM19,'Дек'!$J$44:$L$143)+SUMIF('Янв'!$E$44:$I$143,BM19,'Янв'!$J$44:$L$143)+SUMIF('Фев'!$E$44:$I$143,BM19,'Фев'!$J$44:$L$143)+SUMIF('Мар'!$E$44:$I$143,BM19,'Мар'!$J$44:$L$143)+SUMIF('Апр'!$E$44:$I$143,BM19,'Апр'!$J$44:$L$143)+SUMIF('Май'!$E$44:$I$143,BM19,'Май'!$J$44:$L$143)+SUMIF('Июн'!$E$44:$I$143,BM19,'Июн'!$J$44:$L$143)+SUMIF('Июл'!$E$44:$I$143,BM19,'Июл'!$J$44:$L$143)+SUMIF('Авг'!$E$44:$I$143,BM19,'Авг'!$J$44:$L$143)+SUMIF('Сен'!$E$44:$I$143,BM19,'Сен'!$J$44:$L$143)+SUMIF('Окт'!$E$44:$I$143,BM19,'Окт'!$J$44:$L$143) -> #N/A | BO19: ='Настройка'!B24 -> #REF! | BP19: =SUMIF('Ноя'!$W$44:$AA$143,BO19,'Ноя'!$AB$44:$AD$143)+SUMIF('Дек'!$W$44:$AA$143,BO19,'Дек'!$AB$44:$AD$143)+SUMIF('Янв'!$W$44:$AA$143,BO19,'Янв'!$AB$44:$AD$143)+SUMIF('Фев'!$W$44:$AA$143,BO19,'Фев'!$AB$44:$AD$143)+SUMIF('Мар'!$W$44:$AA$143,BO19,'Мар'!$AB$44:$AD$143)+SUMIF('Апр'!$W$44:$AA$143,BO19,'Апр'!$AB$44:$AD$143)+SUMIF('Май'!$W$44:$AA$143,BO19,'Май'!$AB$44:$AD$143)+SUMIF('Июн'!$W$44:$AA$143,BO19,'Июн'!$AB$44:$AD$143)+SUMIF('Июл'!$W$44:$AA$143,BO19,'Июл'!$AB$44:$AD$143)+SUMIF('Авг'!$W$44:$AA$143,BO19,'Авг'!$AB$44:$AD$143)+SUMIF('Сен'!$W$44:$AA$143,BO19,'Сен'!$AB$44:$AD$143)+SUMIF('Окт'!$W$44:$AA$143,BO19,'Окт'!$AB$44:$AD$143) -> #N/A
AR20: ='Настройка'!E23 -> #REF! | AV20: ='Настройка'!B23 -> #REF! | AZ20: ='Настройка'!B22 -> #REF! | BM20: ='Настройка'!E25 -> #REF! | BN20: =SUMIF('Ноя'!$E$44:$I$143,BM20,'Ноя'!$J$44:$L$143)+SUMIF('Дек'!$E$44:$I$143,BM20,'Дек'!$J$44:$L$143)+SUMIF('Янв'!$E$44:$I$143,BM20,'Янв'!$J$44:$L$143)+SUMIF('Фев'!$E$44:$I$143,BM20,'Фев'!$J$44:$L$143)+SUMIF('Мар'!$E$44:$I$143,BM20,'Мар'!$J$44:$L$143)+SUMIF('Апр'!$E$44:$I$143,BM20,'Апр'!$J$44:$L$143)+SUMIF('Май'!$E$44:$I$143,BM20,'Май'!$J$44:$L$143)+SUMIF('Июн'!$E$44:$I$143,BM20,'Июн'!$J$44:$L$143)+SUMIF('Июл'!$E$44:$I$143,BM20,'Июл'!$J$44:$L$143)+SUMIF('Авг'!$E$44:$I$143,BM20,'Авг'!$J$44:$L$143)+SUMIF('Сен'!$E$44:$I$143,BM20,'Сен'!$J$44:$L$143)+SUMIF('Окт'!$E$44:$I$143,BM20,'Окт'!$J$44:$L$143) -> #N/A | BO20: ='Настройка'!B25 -> #REF! | BP20: =SUMIF('Ноя'!$W$44:$AA$143,BO20,'Ноя'!$AB$44:$AD$143)+SUMIF('Дек'!$W$44:$AA$143,BO20,'Дек'!$AB$44:$AD$143)+SUMIF('Янв'!$W$44:$AA$143,BO20,'Янв'!$AB$44:$AD$143)+SUMIF('Фев'!$W$44:$AA$143,BO20,'Фев'!$AB$44:$AD$143)+SUMIF('Мар'!$W$44:$AA$143,BO20,'Мар'!$AB$44:$AD$143)+SUMIF('Апр'!$W$44:$AA$143,BO20,'Апр'!$AB$44:$AD$143)+SUMIF('Май'!$W$44:$AA$143,BO20,'Май'!$AB$44:$AD$143)+SUMIF('Июн'!$W$44:$AA$143,BO20,'Июн'!$AB$44:$AD$143)+SUMIF('Июл'!$W$44:$AA$143,BO20,'Июл'!$AB$44:$AD$143)+SUMIF('Авг'!$W$44:$AA$143,BO20,'Авг'!$AB$44:$AD$143)+SUMIF('Сен'!$W$44:$AA$143,BO20,'Сен'!$AB$44:$AD$143)+SUMIF('Окт'!$W$44:$AA$143,BO20,'Окт'!$AB$44:$AD$143) -> #N/A
AR21: ='Настройка'!E24 -> #REF! | AV21: ='Настройка'!B24 -> #REF! | BM21: ='Настройка'!E26 -> #REF! | BN21: =SUMIF('Ноя'!$E$44:$I$143,BM21,'Ноя'!$J$44:$L$143)+SUMIF('Дек'!$E$44:$I$143,BM21,'Дек'!$J$44:$L$143)+SUMIF('Янв'!$E$44:$I$143,BM21,'Янв'!$J$44:$L$143)+SUMIF('Фев'!$E$44:$I$143,BM21,'Фев'!$J$44:$L$143)+SUMIF('Мар'!$E$44:$I$143,BM21,'Мар'!$J$44:$L$143)+SUMIF('Апр'!$E$44:$I$143,BM21,'Апр'!$J$44:$L$143)+SUMIF('Май'!$E$44:$I$143,BM21,'Май'!$J$44:$L$143)+SUMIF('Июн'!$E$44:$I$143,BM21,'Июн'!$J$44:$L$143)+SUMIF('Июл'!$E$44:$I$143,BM21,'Июл'!$J$44:$L$143)+SUMIF('Авг'!$E$44:$I$143,BM21,'Авг'!$J$44:$L$143)+SUMIF('Сен'!$E$44:$I$143,BM21,'Сен'!$J$44:$L$143)+SUMIF('Окт'!$E$44:$I$143,BM21,'Окт'!$J$44:$L$143) -> #N/A | BO21: ='Настройка'!B26 -> #REF! | BP21: =SUMIF('Ноя'!$W$44:$AA$143,BO21,'Ноя'!$AB$44:$AD$143)+SUMIF('Дек'!$W$44:$AA$143,BO21,'Дек'!$AB$44:$AD$143)+SUMIF('Янв'!$W$44:$AA$143,BO21,'Янв'!$AB$44:$AD$143)+SUMIF('Фев'!$W$44:$AA$143,BO21,'Фев'!$AB$44:$AD$143)+SUMIF('Мар'!$W$44:$AA$143,BO21,'Мар'!$AB$44:$AD$143)+SUMIF('Апр'!$W$44:$AA$143,BO21,'Апр'!$AB$44:$AD$143)+SUMIF('Май'!$W$44:$AA$143,BO21,'Май'!$AB$44:$AD$143)+SUMIF('Июн'!$W$44:$AA$143,BO21,'Июн'!$AB$44:$AD$143)+SUMIF('Июл'!$W$44:$AA$143,BO21,'Июл'!$AB$44:$AD$143)+SUMIF('Авг'!$W$44:$AA$143,BO21,'Авг'!$AB$44:$AD$143)+SUMIF('Сен'!$W$44:$AA$143,BO21,'Сен'!$AB$44:$AD$143)+SUMIF('Окт'!$W$44:$AA$143,BO21,'Окт'!$AB$44:$AD$143) -> #N/A
AR22: ='Настройка'!E25 -> #REF! | AV22: ='Настройка'!B25 -> #REF! | BM22: ='Настройка'!E27 -> #REF! | BN22: =SUMIF('Ноя'!$E$44:$I$143,BM22,'Ноя'!$J$44:$L$143)+SUMIF('Дек'!$E$44:$I$143,BM22,'Дек'!$J$44:$L$143)+SUMIF('Янв'!$E$44:$I$143,BM22,'Янв'!$J$44:$L$143)+SUMIF('Фев'!$E$44:$I$143,BM22,'Фев'!$J$44:$L$143)+SUMIF('Мар'!$E$44:$I$143,BM22,'Мар'!$J$44:$L$143)+SUMIF('Апр'!$E$44:$I$143,BM22,'Апр'!$J$44:$L$143)+SUMIF('Май'!$E$44:$I$143,BM22,'Май'!$J$44:$L$143)+SUMIF('Июн'!$E$44:$I$143,BM22,'Июн'!$J$44:$L$143)+SUMIF('Июл'!$E$44:$I$143,BM22,'Июл'!$J$44:$L$143)+SUMIF('Авг'!$E$44:$I$143,BM22,'Авг'!$J$44:$L$143)+SUMIF('Сен'!$E$44:$I$143,BM22,'Сен'!$J$44:$L$143)+SUMIF('Окт'!$E$44:$I$143,BM22,'Окт'!$J$44:$L$143) -> #N/A | BO22: ='Настройка'!B27 -> #REF! | BP22: =SUMIF('Ноя'!$W$44:$AA$143,BO22,'Ноя'!$AB$44:$AD$143)+SUMIF('Дек'!$W$44:$AA$143,BO22,'Дек'!$AB$44:$AD$143)+SUMIF('Янв'!$W$44:$AA$143,BO22,'Янв'!$AB$44:$AD$143)+SUMIF('Фев'!$W$44:$AA$143,BO22,'Фев'!$AB$44:$AD$143)+SUMIF('Мар'!$W$44:$AA$143,BO22,'Мар'!$AB$44:$AD$143)+SUMIF('Апр'!$W$44:$AA$143,BO22,'Апр'!$AB$44:$AD$143)+SUMIF('Май'!$W$44:$AA$143,BO22,'Май'!$AB$44:$AD$143)+SUMIF('Июн'!$W$44:$AA$143,BO22,'Июн'!$AB$44:$AD$143)+SUMIF('Июл'!$W$44:$AA$143,BO22,'Июл'!$AB$44:$AD$143)+SUMIF('Авг'!$W$44:$AA$143,BO22,'Авг'!$AB$44:$AD$143)+SUMIF('Сен'!$W$44:$AA$143,BO22,'Сен'!$AB$44:$AD$143)+SUMIF('Окт'!$W$44:$AA$143,BO22,'Окт'!$AB$44:$AD$143) -> #N/A
AR23: ='Настройка'!E26 -> #REF! | AV23: ='Настройка'!B26 -> #REF! | BM23: ='Настройка'!E28 -> #REF! | BN23: =SUMIF('Ноя'!$E$44:$I$143,BM23,'Ноя'!$J$44:$L$143)+SUMIF('Дек'!$E$44:$I$143,BM23,'Дек'!$J$44:$L$143)+SUMIF('Янв'!$E$44:$I$143,BM23,'Янв'!$J$44:$L$143)+SUMIF('Фев'!$E$44:$I$143,BM23,'Фев'!$J$44:$L$143)+SUMIF('Мар'!$E$44:$I$143,BM23,'Мар'!$J$44:$L$143)+SUMIF('Апр'!$E$44:$I$143,BM23,'Апр'!$J$44:$L$143)+SUMIF('Май'!$E$44:$I$143,BM23,'Май'!$J$44:$L$143)+SUMIF('Июн'!$E$44:$I$143,BM23,'Июн'!$J$44:$L$143)+SUMIF('Июл'!$E$44:$I$143,BM23,'Июл'!$J$44:$L$143)+SUMIF('Авг'!$E$44:$I$143,BM23,'Авг'!$J$44:$L$143)+SUMIF('Сен'!$E$44:$I$143,BM23,'Сен'!$J$44:$L$143)+SUMIF('Окт'!$E$44:$I$143,BM23,'Окт'!$J$44:$L$143) -> #N/A | BO23: ='Настройка'!B28 -> #REF! | BP23: =SUMIF('Ноя'!$W$44:$AA$143,BO23,'Ноя'!$AB$44:$AD$143)+SUMIF('Дек'!$W$44:$AA$143,BO23,'Дек'!$AB$44:$AD$143)+SUMIF('Янв'!$W$44:$AA$143,BO23,'Янв'!$AB$44:$AD$143)+SUMIF('Фев'!$W$44:$AA$143,BO23,'Фев'!$AB$44:$AD$143)+SUMIF('Мар'!$W$44:$AA$143,BO23,'Мар'!$AB$44:$AD$143)+SUMIF('Апр'!$W$44:$AA$143,BO23,'Апр'!$AB$44:$AD$143)+SUMIF('Май'!$W$44:$AA$143,BO23,'Май'!$AB$44:$AD$143)+SUMIF('Июн'!$W$44:$AA$143,BO23,'Июн'!$AB$44:$AD$143)+SUMIF('Июл'!$W$44:$AA$143,BO23,'Июл'!$AB$44:$AD$143)+SUMIF('Авг'!$W$44:$AA$143,BO23,'Авг'!$AB$44:$AD$143)+SUMIF('Сен'!$W$44:$AA$143,BO23,'Сен'!$AB$44:$AD$143)+SUMIF('Окт'!$W$44:$AA$143,BO23,'Окт'!$AB$44:$AD$143) -> #N/A
AR24: ='Настройка'!E27 -> #REF! | AV24: ='Настройка'!B27 -> #REF! | BM24: ='Настройка'!E29 -> #REF! | BN24: =SUMIF('Ноя'!$E$44:$I$143,BM24,'Ноя'!$J$44:$L$143)+SUMIF('Дек'!$E$44:$I$143,BM24,'Дек'!$J$44:$L$143)+SUMIF('Янв'!$E$44:$I$143,BM24,'Янв'!$J$44:$L$143)+SUMIF('Фев'!$E$44:$I$143,BM24,'Фев'!$J$44:$L$143)+SUMIF('Мар'!$E$44:$I$143,BM24,'Мар'!$J$44:$L$143)+SUMIF('Апр'!$E$44:$I$143,BM24,'Апр'!$J$44:$L$143)+SUMIF('Май'!$E$44:$I$143,BM24,'Май'!$J$44:$L$143)+SUMIF('Июн'!$E$44:$I$143,BM24,'Июн'!$J$44:$L$143)+SUMIF('Июл'!$E$44:$I$143,BM24,'Июл'!$J$44:$L$143)+SUMIF('Авг'!$E$44:$I$143,BM24,'Авг'!$J$44:$L$143)+SUMIF('Сен'!$E$44:$I$143,BM24,'Сен'!$J$44:$L$143)+SUMIF('Окт'!$E$44:$I$143,BM24,'Окт'!$J$44:$L$143) -> #N/A | BO24: ='Настройка'!B29 -> #REF! | BP24: =SUMIF('Ноя'!$W$44:$AA$143,BO24,'Ноя'!$AB$44:$AD$143)+SUMIF('Дек'!$W$44:$AA$143,BO24,'Дек'!$AB$44:$AD$143)+SUMIF('Янв'!$W$44:$AA$143,BO24,'Янв'!$AB$44:$AD$143)+SUMIF('Фев'!$W$44:$AA$143,BO24,'Фев'!$AB$44:$AD$143)+SUMIF('Мар'!$W$44:$AA$143,BO24,'Мар'!$AB$44:$AD$143)+SUMIF('Апр'!$W$44:$AA$143,BO24,'Апр'!$AB$44:$AD$143)+SUMIF('Май'!$W$44:$AA$143,BO24,'Май'!$AB$44:$AD$143)+SUMIF('Июн'!$W$44:$AA$143,BO24,'Июн'!$AB$44:$AD$143)+SUMIF('Июл'!$W$44:$AA$143,BO24,'Июл'!$AB$44:$AD$143)+SUMIF('Авг'!$W$44:$AA$143,BO24,'Авг'!$AB$44:$AD$143)+SUMIF('Сен'!$W$44:$AA$143,BO24,'Сен'!$AB$44:$AD$143)+SUMIF('Окт'!$W$44:$AA$143,BO24,'Окт'!$AB$44:$AD$143) -> #N/A
AR25: ='Настройка'!E28 -> #REF! | AV25: ='Настройка'!B28 -> #REF! | BM25: ='Настройка'!E30 -> #REF! | BN25: =SUMIF('Ноя'!$E$44:$I$143,BM25,'Ноя'!$J$44:$L$143)+SUMIF('Дек'!$E$44:$I$143,BM25,'Дек'!$J$44:$L$143)+SUMIF('Янв'!$E$44:$I$143,BM25,'Янв'!$J$44:$L$143)+SUMIF('Фев'!$E$44:$I$143,BM25,'Фев'!$J$44:$L$143)+SUMIF('Мар'!$E$44:$I$143,BM25,'Мар'!$J$44:$L$143)+SUMIF('Апр'!$E$44:$I$143,BM25,'Апр'!$J$44:$L$143)+SUMIF('Май'!$E$44:$I$143,BM25,'Май'!$J$44:$L$143)+SUMIF('Июн'!$E$44:$I$143,BM25,'Июн'!$J$44:$L$143)+SUMIF('Июл'!$E$44:$I$143,BM25,'Июл'!$J$44:$L$143)+SUMIF('Авг'!$E$44:$I$143,BM25,'Авг'!$J$44:$L$143)+SUMIF('Сен'!$E$44:$I$143,BM25,'Сен'!$J$44:$L$143)+SUMIF('Окт'!$E$44:$I$143,BM25,'Окт'!$J$44:$L$143) -> #N/A | BO25: ='Настройка'!B30 -> #REF! | BP25: =SUMIF('Ноя'!$W$44:$AA$143,BO25,'Ноя'!$AB$44:$AD$143)+SUMIF('Дек'!$W$44:$AA$143,BO25,'Дек'!$AB$44:$AD$143)+SUMIF('Янв'!$W$44:$AA$143,BO25,'Янв'!$AB$44:$AD$143)+SUMIF('Фев'!$W$44:$AA$143,BO25,'Фев'!$AB$44:$AD$143)+SUMIF('Мар'!$W$44:$AA$143,BO25,'Мар'!$AB$44:$AD$143)+SUMIF('Апр'!$W$44:$AA$143,BO25,'Апр'!$AB$44:$AD$143)+SUMIF('Май'!$W$44:$AA$143,BO25,'Май'!$AB$44:$AD$143)+SUMIF('Июн'!$W$44:$AA$143,BO25,'Июн'!$AB$44:$AD$143)+SUMIF('Июл'!$W$44:$AA$143,BO25,'Июл'!$AB$44:$AD$143)+SUMIF('Авг'!$W$44:$AA$143,BO25,'Авг'!$AB$44:$AD$143)+SUMIF('Сен'!$W$44:$AA$143,BO25,'Сен'!$AB$44:$AD$143)+SUMIF('Окт'!$W$44:$AA$143,BO25,'Окт'!$AB$44:$AD$143) -> #N/A
AR26: ='Настройка'!E29 -> #REF! | AV26: ='Настройка'!B29 -> #REF! | BM26: ='Настройка'!E31 -> #REF! | BN26: =SUMIF('Ноя'!$E$44:$I$143,BM26,'Ноя'!$J$44:$L$143)+SUMIF('Дек'!$E$44:$I$143,BM26,'Дек'!$J$44:$L$143)+SUMIF('Янв'!$E$44:$I$143,BM26,'Янв'!$J$44:$L$143)+SUMIF('Фев'!$E$44:$I$143,BM26,'Фев'!$J$44:$L$143)+SUMIF('Мар'!$E$44:$I$143,BM26,'Мар'!$J$44:$L$143)+SUMIF('Апр'!$E$44:$I$143,BM26,'Апр'!$J$44:$L$143)+SUMIF('Май'!$E$44:$I$143,BM26,'Май'!$J$44:$L$143)+SUMIF('Июн'!$E$44:$I$143,BM26,'Июн'!$J$44:$L$143)+SUMIF('Июл'!$E$44:$I$143,BM26,'Июл'!$J$44:$L$143)+SUMIF('Авг'!$E$44:$I$143,BM26,'Авг'!$J$44:$L$143)+SUMIF('Сен'!$E$44:$I$143,BM26,'Сен'!$J$44:$L$143)+SUMIF('Окт'!$E$44:$I$143,BM26,'Окт'!$J$44:$L$143) -> #N/A | BO26: ='Настройка'!B31 -> #REF! | BP26: =SUMIF('Ноя'!$W$44:$AA$143,BO26,'Ноя'!$AB$44:$AD$143)+SUMIF('Дек'!$W$44:$AA$143,BO26,'Дек'!$AB$44:$AD$143)+SUMIF('Янв'!$W$44:$AA$143,BO26,'Янв'!$AB$44:$AD$143)+SUMIF('Фев'!$W$44:$AA$143,BO26,'Фев'!$AB$44:$AD$143)+SUMIF('Мар'!$W$44:$AA$143,BO26,'Мар'!$AB$44:$AD$143)+SUMIF('Апр'!$W$44:$AA$143,BO26,'Апр'!$AB$44:$AD$143)+SUMIF('Май'!$W$44:$AA$143,BO26,'Май'!$AB$44:$AD$143)+SUMIF('Июн'!$W$44:$AA$143,BO26,'Июн'!$AB$44:$AD$143)+SUMIF('Июл'!$W$44:$AA$143,BO26,'Июл'!$AB$44:$AD$143)+SUMIF('Авг'!$W$44:$AA$143,BO26,'Авг'!$AB$44:$AD$143)+SUMIF('Сен'!$W$44:$AA$143,BO26,'Сен'!$AB$44:$AD$143)+SUMIF('Окт'!$W$44:$AA$143,BO26,'Окт'!$AB$44:$AD$143) -> #N/A
AR27: ='Настройка'!E30 -> #REF! | AV27: ='Настройка'!B30 -> #REF! | BM27: ='Настройка'!E32 -> #REF! | BN27: =SUMIF('Ноя'!$E$44:$I$143,BM27,'Ноя'!$J$44:$L$143)+SUMIF('Дек'!$E$44:$I$143,BM27,'Дек'!$J$44:$L$143)+SUMIF('Янв'!$E$44:$I$143,BM27,'Янв'!$J$44:$L$143)+SUMIF('Фев'!$E$44:$I$143,BM27,'Фев'!$J$44:$L$143)+SUMIF('Мар'!$E$44:$I$143,BM27,'Мар'!$J$44:$L$143)+SUMIF('Апр'!$E$44:$I$143,BM27,'Апр'!$J$44:$L$143)+SUMIF('Май'!$E$44:$I$143,BM27,'Май'!$J$44:$L$143)+SUMIF('Июн'!$E$44:$I$143,BM27,'Июн'!$J$44:$L$143)+SUMIF('Июл'!$E$44:$I$143,BM27,'Июл'!$J$44:$L$143)+SUMIF('Авг'!$E$44:$I$143,BM27,'Авг'!$J$44:$L$143)+SUMIF('Сен'!$E$44:$I$143,BM27,'Сен'!$J$44:$L$143)+SUMIF('Окт'!$E$44:$I$143,BM27,'Окт'!$J$44:$L$143) -> #N/A | BO27: ='Настройка'!B32 -> #REF! | BP27: =SUMIF('Ноя'!$W$44:$AA$143,BO27,'Ноя'!$AB$44:$AD$143)+SUMIF('Дек'!$W$44:$AA$143,BO27,'Дек'!$AB$44:$AD$143)+SUMIF('Янв'!$W$44:$AA$143,BO27,'Янв'!$AB$44:$AD$143)+SUMIF('Фев'!$W$44:$AA$143,BO27,'Фев'!$AB$44:$AD$143)+SUMIF('Мар'!$W$44:$AA$143,BO27,'Мар'!$AB$44:$AD$143)+SUMIF('Апр'!$W$44:$AA$143,BO27,'Апр'!$AB$44:$AD$143)+SUMIF('Май'!$W$44:$AA$143,BO27,'Май'!$AB$44:$AD$143)+SUMIF('Июн'!$W$44:$AA$143,BO27,'Июн'!$AB$44:$AD$143)+SUMIF('Июл'!$W$44:$AA$143,BO27,'Июл'!$AB$44:$AD$143)+SUMIF('Авг'!$W$44:$AA$143,BO27,'Авг'!$AB$44:$AD$143)+SUMIF('Сен'!$W$44:$AA$143,BO27,'Сен'!$AB$44:$AD$143)+SUMIF('Окт'!$W$44:$AA$143,BO27,'Окт'!$AB$44:$AD$143) -> #N/A
AR28: ='Настройка'!E31 -> #REF! | AV28: ='Настройка'!B31 -> #REF! | BM28: ='Настройка'!E33 -> #REF! | BN28: =SUMIF('Ноя'!$E$44:$I$143,BM28,'Ноя'!$J$44:$L$143)+SUMIF('Дек'!$E$44:$I$143,BM28,'Дек'!$J$44:$L$143)+SUMIF('Янв'!$E$44:$I$143,BM28,'Янв'!$J$44:$L$143)+SUMIF('Фев'!$E$44:$I$143,BM28,'Фев'!$J$44:$L$143)+SUMIF('Мар'!$E$44:$I$143,BM28,'Мар'!$J$44:$L$143)+SUMIF('Апр'!$E$44:$I$143,BM28,'Апр'!$J$44:$L$143)+SUMIF('Май'!$E$44:$I$143,BM28,'Май'!$J$44:$L$143)+SUMIF('Июн'!$E$44:$I$143,BM28,'Июн'!$J$44:$L$143)+SUMIF('Июл'!$E$44:$I$143,BM28,'Июл'!$J$44:$L$143)+SUMIF('Авг'!$E$44:$I$143,BM28,'Авг'!$J$44:$L$143)+SUMIF('Сен'!$E$44:$I$143,BM28,'Сен'!$J$44:$L$143)+SUMIF('Окт'!$E$44:$I$143,BM28,'Окт'!$J$44:$L$143) -> #N/A | BO28: ='Настройка'!B33 -> #REF! | BP28: =SUMIF('Ноя'!$W$44:$AA$143,BO28,'Ноя'!$AB$44:$AD$143)+SUMIF('Дек'!$W$44:$AA$143,BO28,'Дек'!$AB$44:$AD$143)+SUMIF('Янв'!$W$44:$AA$143,BO28,'Янв'!$AB$44:$AD$143)+SUMIF('Фев'!$W$44:$AA$143,BO28,'Фев'!$AB$44:$AD$143)+SUMIF('Мар'!$W$44:$AA$143,BO28,'Мар'!$AB$44:$AD$143)+SUMIF('Апр'!$W$44:$AA$143,BO28,'Апр'!$AB$44:$AD$143)+SUMIF('Май'!$W$44:$AA$143,BO28,'Май'!$AB$44:$AD$143)+SUMIF('Июн'!$W$44:$AA$143,BO28,'Июн'!$AB$44:$AD$143)+SUMIF('Июл'!$W$44:$AA$143,BO28,'Июл'!$AB$44:$AD$143)+SUMIF('Авг'!$W$44:$AA$143,BO28,'Авг'!$AB$44:$AD$143)+SUMIF('Сен'!$W$44:$AA$143,BO28,'Сен'!$AB$44:$AD$143)+SUMIF('Окт'!$W$44:$AA$143,BO28,'Окт'!$AB$44:$AD$143) -> #N/A
AR29: ='Настройка'!E32 -> #REF! | AV29: ='Настройка'!B32 -> #REF! | BM29: ='Настройка'!E34 -> #REF! | BN29: =SUMIF('Ноя'!$E$44:$I$143,BM29,'Ноя'!$J$44:$L$143)+SUMIF('Дек'!$E$44:$I$143,BM29,'Дек'!$J$44:$L$143)+SUMIF('Янв'!$E$44:$I$143,BM29,'Янв'!$J$44:$L$143)+SUMIF('Фев'!$E$44:$I$143,BM29,'Фев'!$J$44:$L$143)+SUMIF('Мар'!$E$44:$I$143,BM29,'Мар'!$J$44:$L$143)+SUMIF('Апр'!$E$44:$I$143,BM29,'Апр'!$J$44:$L$143)+SUMIF('Май'!$E$44:$I$143,BM29,'Май'!$J$44:$L$143)+SUMIF('Июн'!$E$44:$I$143,BM29,'Июн'!$J$44:$L$143)+SUMIF('Июл'!$E$44:$I$143,BM29,'Июл'!$J$44:$L$143)+SUMIF('Авг'!$E$44:$I$143,BM29,'Авг'!$J$44:$L$143)+SUMIF('Сен'!$E$44:$I$143,BM29,'Сен'!$J$44:$L$143)+SUMIF('Окт'!$E$44:$I$143,BM29,'Окт'!$J$44:$L$143) -> #N/A | BO29: ='Настройка'!B34 -> #REF! | BP29: =SUMIF('Ноя'!$W$44:$AA$143,BO29,'Ноя'!$AB$44:$AD$143)+SUMIF('Дек'!$W$44:$AA$143,BO29,'Дек'!$AB$44:$AD$143)+SUMIF('Янв'!$W$44:$AA$143,BO29,'Янв'!$AB$44:$AD$143)+SUMIF('Фев'!$W$44:$AA$143,BO29,'Фев'!$AB$44:$AD$143)+SUMIF('Мар'!$W$44:$AA$143,BO29,'Мар'!$AB$44:$AD$143)+SUMIF('Апр'!$W$44:$AA$143,BO29,'Апр'!$AB$44:$AD$143)+SUMIF('Май'!$W$44:$AA$143,BO29,'Май'!$AB$44:$AD$143)+SUMIF('Июн'!$W$44:$AA$143,BO29,'Июн'!$AB$44:$AD$143)+SUMIF('Июл'!$W$44:$AA$143,BO29,'Июл'!$AB$44:$AD$143)+SUMIF('Авг'!$W$44:$AA$143,BO29,'Авг'!$AB$44:$AD$143)+SUMIF('Сен'!$W$44:$AA$143,BO29,'Сен'!$AB$44:$AD$143)+SUMIF('Окт'!$W$44:$AA$143,BO29,'Окт'!$AB$44:$AD$143) -> #N/A
AR30: ='Настройка'!E33 -> #REF! | AV30: ='Настройка'!B33 -> #REF! | AZ30: ='Настройка'!B32 -> #REF! | BM30: ='Настройка'!E35 -> #REF! | BN30: =SUMIF('Ноя'!$E$44:$I$143,BM30,'Ноя'!$J$44:$L$143)+SUMIF('Дек'!$E$44:$I$143,BM30,'Дек'!$J$44:$L$143)+SUMIF('Янв'!$E$44:$I$143,BM30,'Янв'!$J$44:$L$143)+SUMIF('Фев'!$E$44:$I$143,BM30,'Фев'!$J$44:$L$143)+SUMIF('Мар'!$E$44:$I$143,BM30,'Мар'!$J$44:$L$143)+SUMIF('Апр'!$E$44:$I$143,BM30,'Апр'!$J$44:$L$143)+SUMIF('Май'!$E$44:$I$143,BM30,'Май'!$J$44:$L$143)+SUMIF('Июн'!$E$44:$I$143,BM30,'Июн'!$J$44:$L$143)+SUMIF('Июл'!$E$44:$I$143,BM30,'Июл'!$J$44:$L$143)+SUMIF('Авг'!$E$44:$I$143,BM30,'Авг'!$J$44:$L$143)+SUMIF('Сен'!$E$44:$I$143,BM30,'Сен'!$J$44:$L$143)+SUMIF('Окт'!$E$44:$I$143,BM30,'Окт'!$J$44:$L$143) -> #N/A | BO30: ='Настройка'!B35 -> #REF! | BP30: =SUMIF('Ноя'!$W$44:$AA$143,BO30,'Ноя'!$AB$44:$AD$143)+SUMIF('Дек'!$W$44:$AA$143,BO30,'Дек'!$AB$44:$AD$143)+SUMIF('Янв'!$W$44:$AA$143,BO30,'Янв'!$AB$44:$AD$143)+SUMIF('Фев'!$W$44:$AA$143,BO30,'Фев'!$AB$44:$AD$143)+SUMIF('Мар'!$W$44:$AA$143,BO30,'Мар'!$AB$44:$AD$143)+SUMIF('Апр'!$W$44:$AA$143,BO30,'Апр'!$AB$44:$AD$143)+SUMIF('Май'!$W$44:$AA$143,BO30,'Май'!$AB$44:$AD$143)+SUMIF('Июн'!$W$44:$AA$143,BO30,'Июн'!$AB$44:$AD$143)+SUMIF('Июл'!$W$44:$AA$143,BO30,'Июл'!$AB$44:$AD$143)+SUMIF('Авг'!$W$44:$AA$143,BO30,'Авг'!$AB$44:$AD$143)+SUMIF('Сен'!$W$44:$AA$143,BO30,'Сен'!$AB$44:$AD$143)+SUMIF('Окт'!$W$44:$AA$143,BO30,'Окт'!$AB$44:$AD$143) -> #N/A
AR31: ='Настройка'!E34 -> #REF! | AV31: ='Настройка'!B34 -> #REF! | AZ31: ='Настройка'!B33 -> #REF! | BM31: ='Настройка'!E36 -> #REF! | BN31: =SUMIF('Ноя'!$E$44:$I$143,BM31,'Ноя'!$J$44:$L$143)+SUMIF('Дек'!$E$44:$I$143,BM31,'Дек'!$J$44:$L$143)+SUMIF('Янв'!$E$44:$I$143,BM31,'Янв'!$J$44:$L$143)+SUMIF('Фев'!$E$44:$I$143,BM31,'Фев'!$J$44:$L$143)+SUMIF('Мар'!$E$44:$I$143,BM31,'Мар'!$J$44:$L$143)+SUMIF('Апр'!$E$44:$I$143,BM31,'Апр'!$J$44:$L$143)+SUMIF('Май'!$E$44:$I$143,BM31,'Май'!$J$44:$L$143)+SUMIF('Июн'!$E$44:$I$143,BM31,'Июн'!$J$44:$L$143)+SUMIF('Июл'!$E$44:$I$143,BM31,'Июл'!$J$44:$L$143)+SUMIF('Авг'!$E$44:$I$143,BM31,'Авг'!$J$44:$L$143)+SUMIF('Сен'!$E$44:$I$143,BM31,'Сен'!$J$44:$L$143)+SUMIF('Окт'!$E$44:$I$143,BM31,'Окт'!$J$44:$L$143) -> #N/A | BO31: ='Настройка'!B36 -> #REF! | BP31: =SUMIF('Ноя'!$W$44:$AA$143,BO31,'Ноя'!$AB$44:$AD$143)+SUMIF('Дек'!$W$44:$AA$143,BO31,'Дек'!$AB$44:$AD$143)+SUMIF('Янв'!$W$44:$AA$143,BO31,'Янв'!$AB$44:$AD$143)+SUMIF('Фев'!$W$44:$AA$143,BO31,'Фев'!$AB$44:$AD$143)+SUMIF('Мар'!$W$44:$AA$143,BO31,'Мар'!$AB$44:$AD$143)+SUMIF('Апр'!$W$44:$AA$143,BO31,'Апр'!$AB$44:$AD$143)+SUMIF('Май'!$W$44:$AA$143,BO31,'Май'!$AB$44:$AD$143)+SUMIF('Июн'!$W$44:$AA$143,BO31,'Июн'!$AB$44:$AD$143)+SUMIF('Июл'!$W$44:$AA$143,BO31,'Июл'!$AB$44:$AD$143)+SUMIF('Авг'!$W$44:$AA$143,BO31,'Авг'!$AB$44:$AD$143)+SUMIF('Сен'!$W$44:$AA$143,BO31,'Сен'!$AB$44:$AD$143)+SUMIF('Окт'!$W$44:$AA$143,BO31,'Окт'!$AB$44:$AD$143) -> #N/A
AR32: ='Настройка'!E35 -> #REF! | AV32: ='Настройка'!B35 -> #REF! | AZ32: ='Настройка'!B34 -> #REF! | BM32: ='Настройка'!E37 -> #REF! | BN32: =SUMIF('Ноя'!$E$44:$I$143,BM32,'Ноя'!$J$44:$L$143)+SUMIF('Дек'!$E$44:$I$143,BM32,'Дек'!$J$44:$L$143)+SUMIF('Янв'!$E$44:$I$143,BM32,'Янв'!$J$44:$L$143)+SUMIF('Фев'!$E$44:$I$143,BM32,'Фев'!$J$44:$L$143)+SUMIF('Мар'!$E$44:$I$143,BM32,'Мар'!$J$44:$L$143)+SUMIF('Апр'!$E$44:$I$143,BM32,'Апр'!$J$44:$L$143)+SUMIF('Май'!$E$44:$I$143,BM32,'Май'!$J$44:$L$143)+SUMIF('Июн'!$E$44:$I$143,BM32,'Июн'!$J$44:$L$143)+SUMIF('Июл'!$E$44:$I$143,BM32,'Июл'!$J$44:$L$143)+SUMIF('Авг'!$E$44:$I$143,BM32,'Авг'!$J$44:$L$143)+SUMIF('Сен'!$E$44:$I$143,BM32,'Сен'!$J$44:$L$143)+SUMIF('Окт'!$E$44:$I$143,BM32,'Окт'!$J$44:$L$143) -> #N/A | BO32: ='Настройка'!B37 -> #REF! | BP32: =SUMIF('Ноя'!$W$44:$AA$143,BO32,'Ноя'!$AB$44:$AD$143)+SUMIF('Дек'!$W$44:$AA$143,BO32,'Дек'!$AB$44:$AD$143)+SUMIF('Янв'!$W$44:$AA$143,BO32,'Янв'!$AB$44:$AD$143)+SUMIF('Фев'!$W$44:$AA$143,BO32,'Фев'!$AB$44:$AD$143)+SUMIF('Мар'!$W$44:$AA$143,BO32,'Мар'!$AB$44:$AD$143)+SUMIF('Апр'!$W$44:$AA$143,BO32,'Апр'!$AB$44:$AD$143)+SUMIF('Май'!$W$44:$AA$143,BO32,'Май'!$AB$44:$AD$143)+SUMIF('Июн'!$W$44:$AA$143,BO32,'Июн'!$AB$44:$AD$143)+SUMIF('Июл'!$W$44:$AA$143,BO32,'Июл'!$AB$44:$AD$143)+SUMIF('Авг'!$W$44:$AA$143,BO32,'Авг'!$AB$44:$AD$143)+SUMIF('Сен'!$W$44:$AA$143,BO32,'Сен'!$AB$44:$AD$143)+SUMIF('Окт'!$W$44:$AA$143,BO32,'Окт'!$AB$44:$AD$143) -> #N/A
AR33: ='Настройка'!E36 -> #REF! | AV33: ='Настройка'!B36 -> #REF! | AZ33: ='Настройка'!B35 -> #REF! | BL33: долги | BM33: ='Настройка'!G8 -> #REF! | BN33: =SUMIF('Ноя'!$E$44:$I$143,BM33,'Ноя'!$J$44:$L$143)+SUMIF('Дек'!$E$44:$I$143,BM33,'Дек'!$J$44:$L$143)+SUMIF('Янв'!$E$44:$I$143,BM33,'Янв'!$J$44:$L$143)+SUMIF('Фев'!$E$44:$I$143,BM33,'Фев'!$J$44:$L$143)+SUMIF('Мар'!$E$44:$I$143,BM33,'Мар'!$J$44:$L$143)+SUMIF('Апр'!$E$44:$I$143,BM33,'Апр'!$J$44:$L$143)+SUMIF('Май'!$E$44:$I$143,BM33,'Май'!$J$44:$L$143)+SUMIF('Июн'!$E$44:$I$143,BM33,'Июн'!$J$44:$L$143)+SUMIF('Июл'!$E$44:$I$143,BM33,'Июл'!$J$44:$L$143)+SUMIF('Авг'!$E$44:$I$143,BM33,'Авг'!$J$44:$L$143)+SUMIF('Сен'!$E$44:$I$143,BM33,'Сен'!$J$44:$L$143)+SUMIF('Окт'!$E$44:$I$143,BM33,'Окт'!$J$44:$L$143) -> #N/A
AR34: ='Настройка'!E37 -> #REF! | AV34: ='Настройка'!B37 -> #REF! | AZ34: ='Настройка'!B36 -> #REF! | BM34: ='Настройка'!G9 -> #REF! | BN34: =SUMIF('Ноя'!$E$44:$I$143,BM34,'Ноя'!$J$44:$L$143)+SUMIF('Дек'!$E$44:$I$143,BM34,'Дек'!$J$44:$L$143)+SUMIF('Янв'!$E$44:$I$143,BM34,'Янв'!$J$44:$L$143)+SUMIF('Фев'!$E$44:$I$143,BM34,'Фев'!$J$44:$L$143)+SUMIF('Мар'!$E$44:$I$143,BM34,'Мар'!$J$44:$L$143)+SUMIF('Апр'!$E$44:$I$143,BM34,'Апр'!$J$44:$L$143)+SUMIF('Май'!$E$44:$I$143,BM34,'Май'!$J$44:$L$143)+SUMIF('Июн'!$E$44:$I$143,BM34,'Июн'!$J$44:$L$143)+SUMIF('Июл'!$E$44:$I$143,BM34,'Июл'!$J$44:$L$143)+SUMIF('Авг'!$E$44:$I$143,BM34,'Авг'!$J$44:$L$143)+SUMIF('Сен'!$E$44:$I$143,BM34,'Сен'!$J$44:$L$143)+SUMIF('Окт'!$E$44:$I$143,BM34,'Окт'!$J$44:$L$143) -> #N/A
AQ35: Долги | AR35: ='Настройка'!G8 -> #REF! | AV35: ='Настройка'!G37 -> #REF! | AZ35: ='Настройка'!B37 -> #REF! | BM35: ='Настройка'!G10 -> #REF! | BN35: =SUMIF('Ноя'!$E$44:$I$143,BM35,'Ноя'!$J$44:$L$143)+SUMIF('Дек'!$E$44:$I$143,BM35,'Дек'!$J$44:$L$143)+SUMIF('Янв'!$E$44:$I$143,BM35,'Янв'!$J$44:$L$143)+SUMIF('Фев'!$E$44:$I$143,BM35,'Фев'!$J$44:$L$143)+SUMIF('Мар'!$E$44:$I$143,BM35,'Мар'!$J$44:$L$143)+SUMIF('Апр'!$E$44:$I$143,BM35,'Апр'!$J$44:$L$143)+SUMIF('Май'!$E$44:$I$143,BM35,'Май'!$J$44:$L$143)+SUMIF('Июн'!$E$44:$I$143,BM35,'Июн'!$J$44:$L$143)+SUMIF('Июл'!$E$44:$I$143,BM35,'Июл'!$J$44:$L$143)+SUMIF('Авг'!$E$44:$I$143,BM35,'Авг'!$J$44:$L$143)+SUMIF('Сен'!$E$44:$I$143,BM35,'Сен'!$J$44:$L$143)+SUMIF('Окт'!$E$44:$I$143,BM35,'Окт'!$J$44:$L$143) -> #N/A
AR36: ='Настройка'!G9 -> #REF! | BM36: ='Настройка'!G11 -> #REF! | BN36: =SUMIF('Ноя'!$E$44:$I$143,BM36,'Ноя'!$J$44:$L$143)+SUMIF('Дек'!$E$44:$I$143,BM36,'Дек'!$J$44:$L$143)+SUMIF('Янв'!$E$44:$I$143,BM36,'Янв'!$J$44:$L$143)+SUMIF('Фев'!$E$44:$I$143,BM36,'Фев'!$J$44:$L$143)+SUMIF('Мар'!$E$44:$I$143,BM36,'Мар'!$J$44:$L$143)+SUMIF('Апр'!$E$44:$I$143,BM36,'Апр'!$J$44:$L$143)+SUMIF('Май'!$E$44:$I$143,BM36,'Май'!$J$44:$L$143)+SUMIF('Июн'!$E$44:$I$143,BM36,'Июн'!$J$44:$L$143)+SUMIF('Июл'!$E$44:$I$143,BM36,'Июл'!$J$44:$L$143)+SUMIF('Авг'!$E$44:$I$143,BM36,'Авг'!$J$44:$L$143)+SUMIF('Сен'!$E$44:$I$143,BM36,'Сен'!$J$44:$L$143)+SUMIF('Окт'!$E$44:$I$143,BM36,'Окт'!$J$44:$L$143) -> #N/A
AR37: ='Настройка'!G10 -> #REF! | BM37: ='Настройка'!G12 -> #REF! | BN37: =SUMIF('Ноя'!$E$44:$I$143,BM37,'Ноя'!$J$44:$L$143)+SUMIF('Дек'!$E$44:$I$143,BM37,'Дек'!$J$44:$L$143)+SUMIF('Янв'!$E$44:$I$143,BM37,'Янв'!$J$44:$L$143)+SUMIF('Фев'!$E$44:$I$143,BM37,'Фев'!$J$44:$L$143)+SUMIF('Мар'!$E$44:$I$143,BM37,'Мар'!$J$44:$L$143)+SUMIF('Апр'!$E$44:$I$143,BM37,'Апр'!$J$44:$L$143)+SUMIF('Май'!$E$44:$I$143,BM37,'Май'!$J$44:$L$143)+SUMIF('Июн'!$E$44:$I$143,BM37,'Июн'!$J$44:$L$143)+SUMIF('Июл'!$E$44:$I$143,BM37,'Июл'!$J$44:$L$143)+SUMIF('Авг'!$E$44:$I$143,BM37,'Авг'!$J$44:$L$143)+SUMIF('Сен'!$E$44:$I$143,BM37,'Сен'!$J$44:$L$143)+SUMIF('Окт'!$E$44:$I$143,BM37,'Окт'!$J$44:$L$143) -> #N/A
AR38: ='Настройка'!G11 -> #REF! | BM38: ='Настройка'!G13 -> #REF!
AR39: ='Настройка'!G12 -> #REF! | BM39: ='Настройка'!G14 -> #REF!
AR40: ='Настройка'!G13 -> #REF! | BM40: ='Настройка'!G15 -> #REF!
...

Sheet Jan
AQ1: расходы | AR1: ='პარამეტრები'!E8 -> ქირა | AV1: ='პარამეტრები'!B8 -> ხელფასი | AW1: доходы | BA1: Сводка
AR2: ='პარამეტრები'!E9 -> მობილური ტელეფონი | AV2: ='პარამეტრები'!B9 -> ბონუსი | BA2: Наименование | BF2: Plan | BI2: Actual
C3: იანვარი | I3: შემოსავალი | N3: ხარჯი | S3: ბალანსი | X3: მთლიანი ბალანსი | AC3: ვალი | AF3: ტენდენციები | AR3: ='პარამეტრები'!E10 -> ინტერნეტი | AV3: ='პარამეტრები'!B10 -> ფრილანსერობა | BA3: Income | BF3: =S40 -> 0 | BI3: =SUM(AB44:AD143) -> 0
I4: გეგმა | K4: რეალობა | N4: გეგმა | P4: რეალობა | S4: გეგმა | U4: რეალობა | X4: გეგმა | Z4: რეალობა | AC4: =BF7 -> 0 | AF4: გეგმა | AH4: რეალობა | AR4: ='პარამეტრები'!E11 -> დაზღვევა | AV4: ='პარამეტრები'!B11 -> ბიზნესი | BA4: Expenses | BF4: =G40+SUM(AE28:AG39) -> 0 | BI4: =SUM(J44:L143) -> 0
C5: საწყისი თანხა | I5: =BF3 -> 0 | K5: =BI3 -> 0 | N5: =BF4 -> 0 | P5: =BI4 -> 0 | S5: =BF5 -> 0 | U5: =BI5 -> 0 | X5: =BF6 -> 0 | Z5: =BI6 -> 0 | AF5: 0 | AH5: 0 | AR5: ='პარამეტრები'!E12 -> საწევრო | AV5: ='პარამეტრები'!B12 -> ინვესტიციები და დეპოზიტები | BA5: Остаток | BF5: =S40-G40-AE40 -> 0 | BI5: =SUM(AB44:AD143)-SUM(J44:L143) -> 0
AR6: ='პარამეტრები'!E13 -> კომუნალური | AV6: ='პარამეტრები'!B13 -> სხვა შემოსავალი | BA6: Общий остаток | BF6: =F5+BF5 -> 0 | BI6: =F5+BI5 -> 0
AR7: ='პარამეტრები'!E14 -> ოჯახი | AV7: ='პარამეტრები'!B14 -> შემოსავალი ოჯახიდან | BA7: Долги | BF7: =AE40 -> 0
B8: ხარჯები კატეგორიის მიხედვით | N8: გეგმა / რეალობა | Z8: შემოსავალი კატეგორიის მიხედვით | AR8: ='პარამეტრები'!E15 -> შინაური ცხოველები | AV8: ='პარამეტრები'!B15 -> შემოსავალი მესამე პირიდან | BA8: Тренд расходов | BF8: 0
AR9: ='პარამეტრები'!E16 -> პირადი | AV9: ='პარამეტრები'!B16 -> ვალის დაბრუნება | BA9: Тренд доходов | BF9: 0
AR10: ='პარამეტრები'!E17 -> თავის მოვლა | AV10: ='პარამეტრები'!B17 -> ნივთის გაყიდვა
AR11: ='პარამეტრები'!E18 -> ქველმოქმედება | AV11: ='პარამეტრები'!B18 -> სტიპენდია / გრანტი
AR12: ='პარამეტრები'!E19 -> ტრანსპორტი | AV12: ='პარამეტრები'!B19 -> დივიდენდები
AR13: ='პარამეტრები'!E20 -> ტაქსი | AV13: ='პარამეტრები'!B20
AR14: ='პარამეტრები'!E21 -> საჭმელი | AV14: ='პარამეტრები'!B21
AR15: ='პარამეტრები'!E22 -> კაფეები და რესტორნები | AV15: ='პარამეტრები'!B22
AR16: ='პარამეტრები'!E23 -> მანქანა | AV16: ='პარამეტრები'!B23
AR17: ='პარამეტრები'!E24 -> საწვავი | AV17: ='პარამეტრები'!B24
AR18: ='პარამეტრები'!E25 -> მოგზაურობა | AV18: ='პარამეტრები'!B25
AR19: ='პარამეტრები'!E26 -> წამლები | AV19: ='პარამეტრები'!B26
AR20: ='პარამეტრები'!E27 -> გართობა | AV20: ='პარამეტრები'!B27
AR21: ='პარამეტრები'!E28 -> სასმელი | AV21: ='პარამეტრები'!B28
... AR25: ='პარამეტრები'!E32 -> განათლება | AV25: ='პარამეტრები'!B32
B26: დაგეგმილი ხარჯები | N26: დაგეგმილი შემოსავალი | Z26: ვალი | AR26: ='პარამეტრები'!E33 -> სპორტი | AV26: ='პარამეტრები'!B33
B27: წყარო | G27: გეგმა | J27: რეალობა | N27: წყარო | S27: გეგმა | V27: რეალობა | Z27: წყარო | AE27: ვალი | AH27: რეალობა | AR27: ='პარამეტრები'!E34 | AV27: ='პარამეტრები'!B34
J28: =SUMIF($E$44:$I$143,B28,$J$44:$L$143) -> 0 | V28: =SUMIF($W$44:$AA$143,N28,$AB$44:$AD$143) -> 0 | AH28: =SUMIF($E$44:$I$143,Z28,$J$44:$L$143) -> 0 | AR28: ='პარამეტრები'!E35 | AV28: ='პარამეტრები'!B35
J29: =SUMIF($E$44:$I$143,B29,$J$44:$L$143) -> 0 | V29: =SUMIF($W$44:$AA$143,N29,$AB$44:$AD$143) -> 0 | AH29: =SUMIF($E$44:$I$143,Z29,$J$44:$L$143) -> 0 | AR29: ='პარამეტრები'!E36 | AV29: ='პარამეტრები'!B36
J30: =SUMIF($E$44:$I$143,B30,$J$44:$L$143) -> 0 | V30: =SUMIF($W$44:$AA$143,N30,$AB$44:$AD$143) -> 0 | AH30: =SUMIF($E$44:$I$143,Z30,$J$44:$L$143) -> 0 | AR30: ='პარამეტრები'!E37 | AV30: ='პარამეტრები'!B37 | AZ30: ='Настройка'!B32 -> #REF!
J31: =SUMIF($E$44:$I$143,B31,$J$44:$L$143) -> 0 | V31: =SUMIF($W$44:$AA$143,N31,$AB$44:$AD$143) -> 0 | AH31: =SUMIF($E$44:$I$143,Z31,$J$44:$L$143) -> 0 | AR31: ='პარამეტრები'!E38 | AV31: ='პარამეტრები'!B38 | AZ31: ='Настройка'!B33 -> #REF!
J32: =SUMIF($E$44:$I$143,B32,$J$44:$L$143) -> 0 | V32: =SUMIF($W$44:$AA$143,N32,$AB$44:$AD$143) -> 0 | AH32: =SUMIF($E$44:$I$143,Z32,$J$44:$L$143) -> 0 | AR32: ='პარამეტრები'!E39 | AV32: ='პარამეტრები'!B39 | AZ32: ='Настройка'!B34 -> #REF!
J33: =SUMIF($E$44:$I$143,B33,$J$44:$L$143) -> 0 | V33: =SUMIF($W$44:$AA$143,N33,$AB$44:$AD$143) -> 0 | AH33: =SUMIF($E$44:$I$143,Z33,$J$44:$L$143) -> 0 | AR33: ='პარამეტრები'!E40 | AV33: ='პარამეტრები'!B40 | AZ33: ='Настройка'!B35 -> #REF!
J34: =SUMIF($E$44:$I$143,B34,$J$44:$L$143) -> 0 | V34: =SUMIF($W$44:$AA$143,N34,$AB$44:$AD$143) -> 0 | AH34: =SUMIF($E$44:$I$143,Z34,$J$44:$L$143) -> 0 | AR34: ='პარამეტრები'!E41 | AV34: ='პარამეტრები'!B41 | AZ34: ='Настройка'!B36 -> #REF!
J35: =SUMIF($E$44:$I$143,B35,$J$44:$L$143) -> 0 | V35: =SUMIF($W$44:$AA$143,N35,$AB$44:$AD$143) -> 0 | AH35: =SUMIF($E$44:$I$143,Z35,$J$44:$L$143) -> 0 | AQ35: Долги | AR35: ='პარამეტრები'!G8 -> სესხები | AV35: ='პარამეტრები'!B42 | AZ35: ='Настройка'!B37 -> #REF!
J36: =SUMIF($E$44:$I$143,B36,$J$44:$L$143) -> 0 | V36: =SUMIF($W$44:$AA$143,N36,$AB$44:$AD$143) -> 0 | AH36: =SUMIF($E$44:$I$143,Z36,$J$44:$L$143) -> 0 | AR36: ='პარამეტრები'!G9 -> ვალები | AV36: ='პარამეტრები'!B43
